Workbook
Name LastActual: Inputs!$B$3
Name CPLHTol: Inputs!$B$7
Name WageDates: Inputs!$A$21:$A$28
Name WageRates: Inputs!$B$21:$B$28
Name PH_Roster: Inputs!$B$31
Name PH_Loading: Inputs!$B$32
Name SiteCodes: Inputs!$A$36:$A$45

Sheet README
A1: Warehouse payroll forecast model (simple version)
A2: Synthetic data only. Monthly, Jan 2025 to Dec 2028.
A4: THE MODEL (per site, per forecast month)
A5: Sales and payroll % come from the plan (Plan_Inputs). They drive everything.
A6: Total payroll = plan sales x plan payroll %.
A7: Leadership = total payroll x leadership share of total payroll in the same month last year.
A8: Staff payroll = total payroll - leadership.
A9: Cost per hour = same month last year's cost per hour, with last year's public holidays and wage index taken out
A10: and this month's put back in. Hours = staff payroll / cost per hour.
A11: Cases come from the Cases_Forecast tab: volume driver sales x cases per $ in the same month last year,
A12: plus your adjustments, or your override.
A13: CPLH = cases / hours. Cost per case = total payroll / cases.
... A30: Public holidays are generated by rule; check against the official state lists (AFL Grand Final Friday in particular).

Sheet Inputs
A1: Inputs
A3: Last actual month | B3: 46266
A5: Model status | B5: =Checks!B3
A7: Warn if forecast CPLH moves more than this vs LY | B7: 0.1
A19: Wage increases (staff cost per hour)
A20: Effective month | B20: Increase
A21: 46023 | B21: 0.04 | C21: Include past increases too: last year's cost per hour is divided by its wage index before this year's is applied.
A22: 46388 | B22: 0.045
A23: 46753 | B23: 0.045
A30: Public holidays
A31: Share of normal hours worked on a PH | B31: 0.5
A32: PH pay loading (1.5 = paid 250%) | B32: 1.5
A34: Sites | B34: Type your own codes in the Code column; every tab follows. Renaming the tabs to match is optional.
A35: Code | B35: Type | C35: State | D35: Payroll % basis | E35: In national sales? | F35: Volume driver
A36: NSW-1 | B36: Region | C36: NSW | D36: =A36 | E36: Yes | F36: =A36
A37: VIC-1 | B37: Region | C37: VIC | D37: =A37 | E37: Yes | F37: =A37
A38: QLD-1 | B38: Region | C38: QLD | D38: =A38 | E38: Yes | F38: =A38
A39: NSW-2 | B39: Region | C39: NSW | D39: =A39 | E39: Yes | F39: =A39
A40: VIC-2 | B40: Region | C40: VIC | D40: =A40 | E40: Yes | F40: =A40
A41: QLD-2 | B41: Region | C41: QLD | D41: =A41 | E41: Yes | F41: =A41
A42: SA-1 | B42: Region | C42: SA | D42: =A42 | E42: Yes | F42: =A42
A43: WA-1 | B43: Region | C43: WA | D43: =A43 | E43: Yes | F43: =A43
A44: IDC-NSW | B44: IDC | C44: NSW | D44: =A36 | E44: No | F44: =A36&"+"&A39
A45: IDC-VIC | B45: IDC | C45: VIC | D45: =A37 | E45: No | F45: =A37&"+"&A40

Sheet Data_Actuals
A1: Month | B1: Site | C1: Sales $ | D1: Cases picked | E1: WH hours worked | F1: Staff payroll $ | G1: Leadership payroll $
A2: 45658 | B2: =Inputs!$A$36 | C2: 145185523 | D2: 3043624 | E2: 40295 | F2: 2808121 | G2: 319183
A3: 45658 | B3: =Inputs!$A$37 | C3: 133443243 | D3: 2887489 | E3: 38547 | F3: 2623810 | G3: 302699
A4: 45658 | B4: =Inputs!$A$38 | C4: 111417052 | D4: 2452995 | E4: 34693 | F4: 2319628 | G4: 267794
A5: 45658 | B5: =Inputs!$A$39 | C5: 125154901 | D5: 2690106 | E5: 36126 | F5: 2481070 | G5: 301012
A6: 45658 | B6: =Inputs!$A$40 | C6: 129729431 | D6: 2666780 | E6: 34264 | F6: 2298653 | G6: 303403
A7: 45658 | B7: =Inputs!$A$41 | C7: 117129351 | D7: 2537615 | E7: 35430 | F7: 2331622 | G7: 266309
A8: 45658 | B8: =Inputs!$A$42 | C8: 78517402 | D8: 1794006 | E8: 26280 | F8: 1687827 | G8: 204809
A9: 45658 | B9: =Inputs!$A$43 | C9: 99253181 | D9: 2212340 | E9: 31507 | F9: 2336629 | G9: 248935
A10: 45658 | B10: =Inputs!$A$44 | D10: 814235 | E10: 7750 | F10: 564304 | G10: 149724
A11: 45658 | B11: =Inputs!$A$45 | D11: 745617 | E11: 7313 | F11: 524974 | G11: 142777
A12: 45689 | B12: =Inputs!$A$36 | C12: 132346726 | D12: 2785007 | E12: 36181 | F12: 2383806 | G12: 320742
A13: 45689 | B13: =Inputs!$A$37 | C13: 129246596 | D13: 2777283 | E13: 34519 | F13: 2236585 | G13: 295534
A14: 45689 | B14: =Inputs!$A$38 | C14: 100727414 | D14: 2181145 | E14: 29392 | F14: 1832372 | G14: 257979
A15: 45689 | B15: =Inputs!$A$39 | C15: 110794435 | D15: 2337164 | E15: 31366 | F15: 2097121 | G15: 282353
A16: 45689 | B16: =Inputs!$A$40 | C16: 122688392 | D16: 2600981 | E16: 33068 | F16: 2113994 | G16: 294983
A17: 45689 | B17: =Inputs!$A$41 | C17: 109162992 | D17: 2365350 | E17: 31471 | F17: 1991983 | G17: 275619
A18: 45689 | B18: =Inputs!$A$42 | C18: 70749655 | D18: 1615239 | E18: 22417 | F18: 1358641 | G18: 210920
A19: 45689 | B19: =Inputs!$A$43 | C19: 94123598 | D19: 2117036 | E19: 29338 | F19: 2028412 | G19: 245629
A20: 45689 | B20: =Inputs!$A$44 | D20: 736093 | E20: 6714 | F20: 471815 | G20: 145495
A21: 45689 | B21: =Inputs!$A$45 | D21: 699658 | E21: 6848 | F21: 467508 | G21: 140341
A22: 45717 | B22: =Inputs!$A$36 | C22: 151388181 | D22: 3208052 | E22: 40660 | F22: 2685948 | G22: 315275
A23: 45717 | B23: =Inputs!$A$37 | C23: 139380637 | D23: 3034799 | E23: 37316 | F23: 2494850 | G23: 319982
A24: 45717 | B24: =Inputs!$A$38 | C24: 115886017 | D24: 2560673 | E24: 34662 | F24: 2185396 | G24: 255961
A25: 45717 | B25: =Inputs!$A$39 | C25: 123027509 | D25: 2608583 | E25: 33988 | F25: 2237477 | G25: 273167
A26: 45717 | B26: =Inputs!$A$40 | C26: 135907959 | D26: 2829800 | E26: 35242 | F26: 2310290 | G26: 298020
A27: 45717 | B27: =Inputs!$A$41 | C27: 122320621 | D27: 2680744 | E27: 35277 | F27: 2213243 | G27: 268586
A28: 45717 | B28: =Inputs!$A$42 | C28: 81234768 | D28: 1826489 | E28: 24500 | F28: 1538671 | G28: 197429
A29: 45717 | B29: =Inputs!$A$43 | C29: 108067323 | D29: 2388750 | E29: 32485 | F29: 2317422 | G29: 248477
A30: 45717 | B30: =Inputs!$A$44 | D30: 809173 | E30: 7223 | F30: 505153 | G30: 146059
A31: 45717 | B31: =Inputs!$A$45 | D31: 778599 | E31: 7397 | F31: 527308 | G31: 140256
A32: 45748 | B32: =Inputs!$A$36 | C32: 147502978 | D32: 3093483 | E32: 39190 | F32: 2940258 | G32: 319320
A33: 45748 | B33: =Inputs!$A$37 | C33: 139729332 | D33: 3011417 | E33: 37754 | F33: 2783718 | G33: 313897
A34: 45748 | B34: =Inputs!$A$38 | C34: 117059467 | D34: 2552888 | E34: 34584 | F34: 2465776 | G34: 260553
A35: 45748 | B35: =Inputs!$A$39 | C35: 123461416 | D35: 2596120 | E35: 34407 | F35: 2569797 | G35: 284117
A36: 45748 | B36: =Inputs!$A$40 | C36: 136765517 | D36: 2877751 | E36: 35707 | F36: 2629214 | G36: 306586
A37: 45748 | B37: =Inputs!$A$41 | C37: 116536673 | D37: 2538303 | E37: 34449 | F37: 2474166 | G37: 272848
A38: 45748 | B38: =Inputs!$A$42 | C38: 79536351 | D38: 1769687 | E38: 24842 | F38: 1722163 | G38: 207265
A39: 45748 | B39: =Inputs!$A$43 | C39: 104847628 | D39: 2342946 | E39: 32011 | F39: 2424086 | G39: 250907
A40: 45748 | B40: =Inputs!$A$44 | D40: 816972 | E40: 7455 | F40: 606629 | G40: 153750
...

Sheet Plan_Inputs
A1: Month | B1: Site | C1: Sales forecast $ | D1: Payroll % of sales (total) | F1: From the long-range plan. IDC payroll % is a % of the host region's sales (see Sites on Inputs).
A2: 46023 | B2: =Inputs!$A$36 | C2: 153814000 | D2: 0.022
A3: 46023 | B3: =Inputs!$A$37 | C3: 142733000 | D3: 0.0209
A4: 46023 | B4: =Inputs!$A$38 | C4: 117343000 | D4: 0.0223
A5: 46023 | B5: =Inputs!$A$39 | C5: 126585000 | D5: 0.0222
A6: 46023 | B6: =Inputs!$A$40 | C6: 135910000 | D6: 0.021
A7: 46023 | B7: =Inputs!$A$41 | C7: 120851000 | D7: 0.0221
A8: 46023 | B8: =Inputs!$A$42 | C8: 79038000 | D8: 0.0231
A9: 46023 | B9: =Inputs!$A$43 | C9: 106821000 | D9: 0.0267
A10: 46023 | B10: =Inputs!$A$44 | D10: 0.0048
A11: 46023 | B11: =Inputs!$A$45 | D11: 0.005
A12: 46054 | B12: =Inputs!$A$36 | C12: 137092000 | D12: 0.0205
A13: 46054 | B13: =Inputs!$A$37 | C13: 131606000 | D13: 0.0196
A14: 46054 | B14: =Inputs!$A$38 | C14: 109672000 | D14: 0.0218
A15: 46054 | B15: =Inputs!$A$39 | C15: 120059000 | D15: 0.0213
A16: 46054 | B16: =Inputs!$A$40 | C16: 129364000 | D16: 0.0203
A17: 46054 | B17: =Inputs!$A$41 | C17: 114317000 | D17: 0.0211
A18: 46054 | B18: =Inputs!$A$42 | C18: 74441000 | D18: 0.0225
A19: 46054 | B19: =Inputs!$A$43 | C19: 96657000 | D19: 0.0245
A20: 46054 | B20: =Inputs!$A$44 | D20: 0.0048
A21: 46054 | B21: =Inputs!$A$45 | D21: 0.005
A22: 46082 | B22: =Inputs!$A$36 | C22: 157503000 | D22: 0.0202
A23: 46082 | B23: =Inputs!$A$37 | C23: 146942000 | D23: 0.0202
A24: 46082 | B24: =Inputs!$A$38 | C24: 118790000 | D24: 0.0208
A25: 46082 | B25: =Inputs!$A$39 | C25: 132170000 | D25: 0.0201
A26: 46082 | B26: =Inputs!$A$40 | C26: 140523000 | D26: 0.0201
A27: 46082 | B27: =Inputs!$A$41 | C27: 122798000 | D27: 0.0208
A28: 46082 | B28: =Inputs!$A$42 | C28: 81723000 | D28: 0.0222
A29: 46082 | B29: =Inputs!$A$43 | C29: 108203000 | D29: 0.0248
A30: 46082 | B30: =Inputs!$A$44 | D30: 0.0047
A31: 46082 | B31: =Inputs!$A$45 | D31: 0.0047
A32: 46113 | B32: =Inputs!$A$36 | C32: 153091000 | D32: 0.0231
A33: 46113 | B33: =Inputs!$A$37 | C33: 140264000 | D33: 0.0223
A34: 46113 | B34: =Inputs!$A$38 | C34: 116902000 | D34: 0.0238
A35: 46113 | B35: =Inputs!$A$39 | C35: 132565000 | D35: 0.0224
A36: 46113 | B36: =Inputs!$A$40 | C36: 139867000 | D36: 0.0218
A37: 46113 | B37: =Inputs!$A$41 | C37: 125887000 | D37: 0.0229
A38: 46113 | B38: =Inputs!$A$42 | C38: 84196000 | D38: 0.0244
A39: 46113 | B39: =Inputs!$A$43 | C39: 111697000 | D39: 0.0263
A40: 46113 | B40: =Inputs!$A$44 | D40: 0.0051
...

Sheet Cases_Forecast
A1: Cases forecast
A2: 1. Run rate: volume driver sales x cases per $ of sales in the same month last year. Actual months show actuals.
A3: 2. Adjustments: type extra cases (or negative) for a site and month, e.g. a new store or volume moving between sites.
A4: 3. Override: type the cases you want for a site and month. It replaces 1 + 2. Leave blank to use the model.
A5: 4. Cases used = override if there is one, otherwise run rate + adjustment. This feeds Cases picked on each site tab.
C6: 1. Run-rate forecast | N6: 2. Adjustments (+/- cases) | Y6: 3. Override (replaces 1 + 2) | AJ6: 4. Cases forecast used
A7: Month | B7: Status | C7: =Inputs!$A$36 | D7: =Inputs!$A$37 | E7: =Inputs!$A$38 | F7: =Inputs!$A$39 | G7: =Inputs!$A$40 | H7: =Inputs!$A$41 | I7: =Inputs!$A$42 | J7: =Inputs!$A$43 | K7: =Inputs!$A$44 | L7: =Inputs!$A$45 | N7: =Inputs!$A$36 | O7: =Inputs!$A$37 | P7: =Inputs!$A$38 | Q7: =Inputs!$A$39 | R7: =Inputs!$A$40 | S7: =Inputs!$A$41 | T7: =Inputs!$A$42 | U7: =Inputs!$A$43 | V7: =Inputs!$A$44 | W7: =Inputs!$A$45 | Y7: =Inputs!$A$36 | Z7: =Inputs!$A$37 | AA7: =Inputs!$A$38 | AB7: =Inputs!$A$39 | AC7: =Inputs!$A$40 | AD7: =Inputs!$A$41 | AE7: =Inputs!$A$42 | AF7: =Inputs!$A$43 | AG7: =Inputs!$A$44 | AH7: =Inputs!$A$45 | AJ7: =Inputs!$A$36 | AK7: =Inputs!$A$37 | AL7: =Inputs!$A$38 | AM7: =Inputs!$A$39 | AN7: =Inputs!$A$40 | AO7: =Inputs!$A$41 | AP7: =Inputs!$A$42 | AQ7: =Inputs!$A$43 | AR7: =Inputs!$A$44 | AS7: =Inputs!$A$45
A8: 45658 | B8: =IF(A8<=LastActual,"Actual","Forecast") | C8: =IF($B8="Actual",'NSW-1'!S15,IFERROR('NSW-1'!Y15*'NSW-1'!AB15,0)) | D8: =IF($B8="Actual",'VIC-1'!S15,IFERROR('VIC-1'!Y15*'VIC-1'!AB15,0)) | E8: =IF($B8="Actual",'QLD-1'!S15,IFERROR('QLD-1'!Y15*'QLD-1'!AB15,0)) | F8: =IF($B8="Actual",'NSW-2'!S15,IFERROR('NSW-2'!Y15*'NSW-2'!AB15,0)) | G8: =IF($B8="Actual",'VIC-2'!S15,IFERROR('VIC-2'!Y15*'VIC-2'!AB15,0)) | H8: =IF($B8="Actual",'QLD-2'!S15,IFERROR('QLD-2'!Y15*'QLD-2'!AB15,0)) | I8: =IF($B8="Actual",'SA-1'!S15,IFERROR('SA-1'!Y15*'SA-1'!AB15,0)) | J8: =IF($B8="Actual",'WA-1'!S15,IFERROR('WA-1'!Y15*'WA-1'!AB15,0)) | K8: =IF($B8="Actual",'IDC-NSW'!S15,IFERROR('IDC-NSW'!Y15*'IDC-NSW'!AB15,0)) | L8: =IF($B8="Actual",'IDC-VIC'!S15,IFERROR('IDC-VIC'!Y15*'IDC-VIC'!AB15,0)) | AJ8: =IF($B8="Actual",C8,IF(Y8<>"",Y8,C8+N(N8))) | AK8: =IF($B8="Actual",D8,IF(Z8<>"",Z8,D8+N(O8))) | AL8: =IF($B8="Actual",E8,IF(AA8<>"",AA8,E8+N(P8))) | AM8: =IF($B8="Actual",F8,IF(AB8<>"",AB8,F8+N(Q8))) | AN8: =IF($B8="Actual",G8,IF(AC8<>"",AC8,G8+N(R8))) | AO8: =IF($B8="Actual",H8,IF(AD8<>"",AD8,H8+N(S8))) | AP8: =IF($B8="Actual",I8,IF(AE8<>"",AE8,I8+N(T8))) | AQ8: =IF($B8="Actual",J8,IF(AF8<>"",AF8,J8+N(U8))) | ... AS8: =IF($B8="Actual",L8,IF(AH8<>"",AH8,L8+N(W8)))
A9: 45689 | B9: =IF(A9<=LastActual,"Actual","Forecast") | C9: =IF($B9="Actual",'NSW-1'!S16,IFERROR('NSW-1'!Y16*'NSW-1'!AB16,0)) | D9: =IF($B9="Actual",'VIC-1'!S16,IFERROR('VIC-1'!Y16*'VIC-1'!AB16,0)) | E9: =IF($B9="Actual",'QLD-1'!S16,IFERROR('QLD-1'!Y16*'QLD-1'!AB16,0)) | F9: =IF($B9="Actual",'NSW-2'!S16,IFERROR('NSW-2'!Y16*'NSW-2'!AB16,0)) | G9: =IF($B9="Actual",'VIC-2'!S16,IFERROR('VIC-2'!Y16*'VIC-2'!AB16,0)) | H9: =IF($B9="Actual",'QLD-2'!S16,IFERROR('QLD-2'!Y16*'QLD-2'!AB16,0)) | I9: =IF($B9="Actual",'SA-1'!S16,IFERROR('SA-1'!Y16*'SA-1'!AB16,0)) | J9: =IF($B9="Actual",'WA-1'!S16,IFERROR('WA-1'!Y16*'WA-1'!AB16,0)) | K9: =IF($B9="Actual",'IDC-NSW'!S16,IFERROR('IDC-NSW'!Y16*'IDC-NSW'!AB16,0)) | L9: =IF($B9="Actual",'IDC-VIC'!S16,IFERROR('IDC-VIC'!Y16*'IDC-VIC'!AB16,0)) | AJ9: =IF($B9="Actual",C9,IF(Y9<>"",Y9,C9+N(N9))) | AK9: =IF($B9="Actual",D9,IF(Z9<>"",Z9,D9+N(O9))) | AL9: =IF($B9="Actual",E9,IF(AA9<>"",AA9,E9+N(P9))) | AM9: =IF($B9="Actual",F9,IF(AB9<>"",AB9,F9+N(Q9))) | AN9: =IF($B9="Actual",G9,IF(AC9<>"",AC9,G9+N(R9))) | AO9: =IF($B9="Actual",H9,IF(AD9<>"",AD9,H9+N(S9))) | AP9: =IF($B9="Actual",I9,IF(AE9<>"",AE9,I9+N(T9))) | AQ9: =IF($B9="Actual",J9,IF(AF9<>"",AF9,J9+N(U9))) | ... AS9: =IF($B9="Actual",L9,IF(AH9<>"",AH9,L9+N(W9)))
A10: 45717 | B10: =IF(A10<=LastActual,"Actual","Forecast") | C10: =IF($B10="Actual",'NSW-1'!S17,IFERROR('NSW-1'!Y17*'NSW-1'!AB17,0)) | D10: =IF($B10="Actual",'VIC-1'!S17,IFERROR('VIC-1'!Y17*'VIC-1'!AB17,0)) | E10: =IF($B10="Actual",'QLD-1'!S17,IFERROR('QLD-1'!Y17*'QLD-1'!AB17,0)) | F10: =IF($B10="Actual",'NSW-2'!S17,IFERROR('NSW-2'!Y17*'NSW-2'!AB17,0)) | G10: =IF($B10="Actual",'VIC-2'!S17,IFERROR('VIC-2'!Y17*'VIC-2'!AB17,0)) | H10: =IF($B10="Actual",'QLD-2'!S17,IFERROR('QLD-2'!Y17*'QLD-2'!AB17,0)) | I10: =IF($B10="Actual",'SA-1'!S17,IFERROR('SA-1'!Y17*'SA-1'!AB17,0)) | J10: =IF($B10="Actual",'WA-1'!S17,IFERROR('WA-1'!Y17*'WA-1'!AB17,0)) | K10: =IF($B10="Actual",'IDC-NSW'!S17,IFERROR('IDC-NSW'!Y17*'IDC-NSW'!AB17,0)) | L10: =IF($B10="Actual",'IDC-VIC'!S17,IFERROR('IDC-VIC'!Y17*'IDC-VIC'!AB17,0)) | AJ10: =IF($B10="Actual",C10,IF(Y10<>"",Y10,C10+N(N10))) | AK10: =IF($B10="Actual",D10,IF(Z10<>"",Z10,D10+N(O10))) | AL10: =IF($B10="Actual",E10,IF(AA10<>"",AA10,E10+N(P10))) | AM10: =IF($B10="Actual",F10,IF(AB10<>"",AB10,F10+N(Q10))) | AN10: =IF($B10="Actual",G10,IF(AC10<>"",AC10,G10+N(R10))) | AO10: =IF($B10="Actual",H10,IF(AD10<>"",AD10,H10+N(S10))) | AP10: =IF($B10="Actual",I10,IF(AE10<>"",AE10,I10+N(T10))) | AQ10: =IF($B10="Actual",J10,IF(AF10<>"",AF10,J10+N(U10))) | ... AS10: =IF($B10="Actual",L10,IF(AH10<>"",AH10,L10+N(W10)))
A11: 45748 | B11: =IF(A11<=LastActual,"Actual","Forecast") | C11: =IF($B11="Actual",'NSW-1'!S18,IFERROR('NSW-1'!Y18*'NSW-1'!AB18,0)) | D11: =IF($B11="Actual",'VIC-1'!S18,IFERROR('VIC-1'!Y18*'VIC-1'!AB18,0)) | E11: =IF($B11="Actual",'QLD-1'!S18,IFERROR('QLD-1'!Y18*'QLD-1'!AB18,0)) | F11: =IF($B11="Actual",'NSW-2'!S18,IFERROR('NSW-2'!Y18*'NSW-2'!AB18,0)) | G11: =IF($B11="Actual",'VIC-2'!S18,IFERROR('VIC-2'!Y18*'VIC-2'!AB18,0)) | H11: =IF($B11="Actual",'QLD-2'!S18,IFERROR('QLD-2'!Y18*'QLD-2'!AB18,0)) | I11: =IF($B11="Actual",'SA-1'!S18,IFERROR('SA-1'!Y18*'SA-1'!AB18,0)) | J11: =IF($B11="Actual",'WA-1'!S18,IFERROR('WA-1'!Y18*'WA-1'!AB18,0)) | K11: =IF($B11="Actual",'IDC-NSW'!S18,IFERROR('IDC-NSW'!Y18*'IDC-NSW'!AB18,0)) | L11: =IF($B11="Actual",'IDC-VIC'!S18,IFERROR('IDC-VIC'!Y18*'IDC-VIC'!AB18,0)) | AJ11: =IF($B11="Actual",C11,IF(Y11<>"",Y11,C11+N(N11))) | AK11: =IF($B11="Actual",D11,IF(Z11<>"",Z11,D11+N(O11))) | AL11: =IF($B11="Actual",E11,IF(AA11<>"",AA11,E11+N(P11))) | AM11: =IF($B11="Actual",F11,IF(AB11<>"",AB11,F11+N(Q11))) | AN11: =IF($B11="Actual",G11,IF(AC11<>"",AC11,G11+N(R11))) | AO11: =IF($B11="Actual",H11,IF(AD11<>"",AD11,H11+N(S11))) | AP11: =IF($B11="Actual",I11,IF(AE11<>"",AE11,I11+N(T11))) | AQ11: =IF($B11="Actual",J11,IF(AF11<>"",AF11,J11+N(U11))) | ... AS11: =IF($B11="Actual",L11,IF(AH11<>"",AH11,L11+N(W11)))
A12: 45778 | B12: =IF(A12<=LastActual,"Actual","Forecast") | C12: =IF($B12="Actual",'NSW-1'!S19,IFERROR('NSW-1'!Y19*'NSW-1'!AB19,0)) | D12: =IF($B12="Actual",'VIC-1'!S19,IFERROR('VIC-1'!Y19*'VIC-1'!AB19,0)) | E12: =IF($B12="Actual",'QLD-1'!S19,IFERROR('QLD-1'!Y19*'QLD-1'!AB19,0)) | F12: =IF($B12="Actual",'NSW-2'!S19,IFERROR('NSW-2'!Y19*'NSW-2'!AB19,0)) | G12: =IF($B12="Actual",'VIC-2'!S19,IFERROR('VIC-2'!Y19*'VIC-2'!AB19,0)) | H12: =IF($B12="Actual",'QLD-2'!S19,IFERROR('QLD-2'!Y19*'QLD-2'!AB19,0)) | I12: =IF($B12="Actual",'SA-1'!S19,IFERROR('SA-1'!Y19*'SA-1'!AB19,0)) | J12: =IF($B12="Actual",'WA-1'!S19,IFERROR('WA-1'!Y19*'WA-1'!AB19,0)) | K12: =IF($B12="Actual",'IDC-NSW'!S19,IFERROR('IDC-NSW'!Y19*'IDC-NSW'!AB19,0)) | L12: =IF($B12="Actual",'IDC-VIC'!S19,IFERROR('IDC-VIC'!Y19*'IDC-VIC'!AB19,0)) | AJ12: =IF($B12="Actual",C12,IF(Y12<>"",Y12,C12+N(N12))) | AK12: =IF($B12="Actual",D12,IF(Z12<>"",Z12,D12+N(O12))) | AL12: =IF($B12="Actual",E12,IF(AA12<>"",AA12,E12+N(P12))) | AM12: =IF($B12="Actual",F12,IF(AB12<>"",AB12,F12+N(Q12))) | AN12: =IF($B12="Actual",G12,IF(AC12<>"",AC12,G12+N(R12))) | AO12: =IF($B12="Actual",H12,IF(AD12<>"",AD12,H12+N(S12))) | AP12: =IF($B12="Actual",I12,IF(AE12<>"",AE12,I12+N(T12))) | AQ12: =IF($B12="Actual",J12,IF(AF12<>"",AF12,J12+N(U12))) | ... AS12: =IF($B12="Actual",L12,IF(AH12<>"",AH12,L12+N(W12)))
A13: 45809 | B13: =IF(A13<=LastActual,"Actual","Forecast") | C13: =IF($B13="Actual",'NSW-1'!S20,IFERROR('NSW-1'!Y20*'NSW-1'!AB20,0)) | D13: =IF($B13="Actual",'VIC-1'!S20,IFERROR('VIC-1'!Y20*'VIC-1'!AB20,0)) | E13: =IF($B13="Actual",'QLD-1'!S20,IFERROR('QLD-1'!Y20*'QLD-1'!AB20,0)) | F13: =IF($B13="Actual",'NSW-2'!S20,IFERROR('NSW-2'!Y20*'NSW-2'!AB20,0)) | G13: =IF($B13="Actual",'VIC-2'!S20,IFERROR('VIC-2'!Y20*'VIC-2'!AB20,0)) | H13: =IF($B13="Actual",'QLD-2'!S20,IFERROR('QLD-2'!Y20*'QLD-2'!AB20,0)) | I13: =IF($B13="Actual",'SA-1'!S20,IFERROR('SA-1'!Y20*'SA-1'!AB20,0)) | J13: =IF($B13="Actual",'WA-1'!S20,IFERROR('WA-1'!Y20*'WA-1'!AB20,0)) | K13: =IF($B13="Actual",'IDC-NSW'!S20,IFERROR('IDC-NSW'!Y20*'IDC-NSW'!AB20,0)) | L13: =IF($B13="Actual",'IDC-VIC'!S20,IFERROR('IDC-VIC'!Y20*'IDC-VIC'!AB20,0)) | AJ13: =IF($B13="Actual",C13,IF(Y13<>"",Y13,C13+N(N13))) | AK13: =IF($B13="Actual",D13,IF(Z13<>"",Z13,D13+N(O13))) | AL13: =IF($B13="Actual",E13,IF(AA13<>"",AA13,E13+N(P13))) | AM13: =IF($B13="Actual",F13,IF(AB13<>"",AB13,F13+N(Q13))) | AN13: =IF($B13="Actual",G13,IF(AC13<>"",AC13,G13+N(R13))) | AO13: =IF($B13="Actual",H13,IF(AD13<>"",AD13,H13+N(S13))) | AP13: =IF($B13="Actual",I13,IF(AE13<>"",AE13,I13+N(T13))) | AQ13: =IF($B13="Actual",J13,IF(AF13<>"",AF13,J13+N(U13))) | ... AS13: =IF($B13="Actual",L13,IF(AH13<>"",AH13,L13+N(W13)))
A14: 45839 | B14: =IF(A14<=LastActual,"Actual","Forecast") | C14: =IF($B14="Actual",'NSW-1'!S21,IFERROR('NSW-1'!Y21*'NSW-1'!AB21,0)) | D14: =IF($B14="Actual",'VIC-1'!S21,IFERROR('VIC-1'!Y21*'VIC-1'!AB21,0)) | E14: =IF($B14="Actual",'QLD-1'!S21,IFERROR('QLD-1'!Y21*'QLD-1'!AB21,0)) | F14: =IF($B14="Actual",'NSW-2'!S21,IFERROR('NSW-2'!Y21*'NSW-2'!AB21,0)) | G14: =IF($B14="Actual",'VIC-2'!S21,IFERROR('VIC-2'!Y21*'VIC-2'!AB21,0)) | H14: =IF($B14="Actual",'QLD-2'!S21,IFERROR('QLD-2'!Y21*'QLD-2'!AB21,0)) | I14: =IF($B14="Actual",'SA-1'!S21,IFERROR('SA-1'!Y21*'SA-1'!AB21,0)) | J14: =IF($B14="Actual",'WA-1'!S21,IFERROR('WA-1'!Y21*'WA-1'!AB21,0)) | K14: =IF($B14="Actual",'IDC-NSW'!S21,IFERROR('IDC-NSW'!Y21*'IDC-NSW'!AB21,0)) | L14: =IF($B14="Actual",'IDC-VIC'!S21,IFERROR('IDC-VIC'!Y21*'IDC-VIC'!AB21,0)) | AJ14: =IF($B14="Actual",C14,IF(Y14<>"",Y14,C14+N(N14))) | AK14: =IF($B14="Actual",D14,IF(Z14<>"",Z14,D14+N(O14))) | AL14: =IF($B14="Actual",E14,IF(AA14<>"",AA14,E14+N(P14))) | AM14: =IF($B14="Actual",F14,IF(AB14<>"",AB14,F14+N(Q14))) | AN14: =IF($B14="Actual",G14,IF(AC14<>"",AC14,G14+N(R14))) | AO14: =IF($B14="Actual",H14,IF(AD14<>"",AD14,H14+N(S14))) | AP14: =IF($B14="Actual",I14,IF(AE14<>"",AE14,I14+N(T14))) | AQ14: =IF($B14="Actual",J14,IF(AF14<>"",AF14,J14+N(U14))) | ... AS14: =IF($B14="Actual",L14,IF(AH14<>"",AH14,L14+N(W14)))
A15: 45870 | B15: =IF(A15<=LastActual,"Actual","Forecast") | C15: =IF($B15="Actual",'NSW-1'!S22,IFERROR('NSW-1'!Y22*'NSW-1'!AB22,0)) | D15: =IF($B15="Actual",'VIC-1'!S22,IFERROR('VIC-1'!Y22*'VIC-1'!AB22,0)) | E15: =IF($B15="Actual",'QLD-1'!S22,IFERROR('QLD-1'!Y22*'QLD-1'!AB22,0)) | F15: =IF($B15="Actual",'NSW-2'!S22,IFERROR('NSW-2'!Y22*'NSW-2'!AB22,0)) | G15: =IF($B15="Actual",'VIC-2'!S22,IFERROR('VIC-2'!Y22*'VIC-2'!AB22,0)) | H15: =IF($B15="Actual",'QLD-2'!S22,IFERROR('QLD-2'!Y22*'QLD-2'!AB22,0)) | I15: =IF($B15="Actual",'SA-1'!S22,IFERROR('SA-1'!Y22*'SA-1'!AB22,0)) | J15: =IF($B15="Actual",'WA-1'!S22,IFERROR('WA-1'!Y22*'WA-1'!AB22,0)) | K15: =IF($B15="Actual",'IDC-NSW'!S22,IFERROR('IDC-NSW'!Y22*'IDC-NSW'!AB22,0)) | L15: =IF($B15="Actual",'IDC-VIC'!S22,IFERROR('IDC-VIC'!Y22*'IDC-VIC'!AB22,0)) | AJ15: =IF($B15="Actual",C15,IF(Y15<>"",Y15,C15+N(N15))) | AK15: =IF($B15="Actual",D15,IF(Z15<>"",Z15,D15+N(O15))) | AL15: =IF($B15="Actual",E15,IF(AA15<>"",AA15,E15+N(P15))) | AM15: =IF($B15="Actual",F15,IF(AB15<>"",AB15,F15+N(Q15))) | AN15: =IF($B15="Actual",G15,IF(AC15<>"",AC15,G15+N(R15))) | AO15: =IF($B15="Actual",H15,IF(AD15<>"",AD15,H15+N(S15))) | AP15: =IF($B15="Actual",I15,IF(AE15<>"",AE15,I15+N(T15))) | AQ15: =IF($B15="Actual",J15,IF(AF15<>"",AF15,J15+N(U15))) | ... AS15: =IF($B15="Actual",L15,IF(AH15<>"",AH15,L15+N(W15)))
A16: 45901 | B16: =IF(A16<=LastActual,"Actual","Forecast") | C16: =IF($B16="Actual",'NSW-1'!S23,IFERROR('NSW-1'!Y23*'NSW-1'!AB23,0)) | D16: =IF($B16="Actual",'VIC-1'!S23,IFERROR('VIC-1'!Y23*'VIC-1'!AB23,0)) | E16: =IF($B16="Actual",'QLD-1'!S23,IFERROR('QLD-1'!Y23*'QLD-1'!AB23,0)) | F16: =IF($B16="Actual",'NSW-2'!S23,IFERROR('NSW-2'!Y23*'NSW-2'!AB23,0)) | G16: =IF($B16="Actual",'VIC-2'!S23,IFERROR('VIC-2'!Y23*'VIC-2'!AB23,0)) | H16: =IF($B16="Actual",'QLD-2'!S23,IFERROR('QLD-2'!Y23*'QLD-2'!AB23,0)) | I16: =IF($B16="Actual",'SA-1'!S23,IFERROR('SA-1'!Y23*'SA-1'!AB23,0)) | J16: =IF($B16="Actual",'WA-1'!S23,IFERROR('WA-1'!Y23*'WA-1'!AB23,0)) | K16: =IF($B16="Actual",'IDC-NSW'!S23,IFERROR('IDC-NSW'!Y23*'IDC-NSW'!AB23,0)) | L16: =IF($B16="Actual",'IDC-VIC'!S23,IFERROR('IDC-VIC'!Y23*'IDC-VIC'!AB23,0)) | AJ16: =IF($B16="Actual",C16,IF(Y16<>"",Y16,C16+N(N16))) | AK16: =IF($B16="Actual",D16,IF(Z16<>"",Z16,D16+N(O16))) | AL16: =IF($B16="Actual",E16,IF(AA16<>"",AA16,E16+N(P16))) | AM16: =IF($B16="Actual",F16,IF(AB16<>"",AB16,F16+N(Q16))) | AN16: =IF($B16="Actual",G16,IF(AC16<>"",AC16,G16+N(R16))) | AO16: =IF($B16="Actual",H16,IF(AD16<>"",AD16,H16+N(S16))) | AP16: =IF($B16="Actual",I16,IF(AE16<>"",AE16,I16+N(T16))) | AQ16: =IF($B16="Actual",J16,IF(AF16<>"",AF16,J16+N(U16))) | ... AS16: =IF($B16="Actual",L16,IF(AH16<>"",AH16,L16+N(W16)))
A17: 45931 | B17: =IF(A17<=LastActual,"Actual","Forecast") | C17: =IF($B17="Actual",'NSW-1'!S24,IFERROR('NSW-1'!Y24*'NSW-1'!AB24,0)) | D17: =IF($B17="Actual",'VIC-1'!S24,IFERROR('VIC-1'!Y24*'VIC-1'!AB24,0)) | E17: =IF($B17="Actual",'QLD-1'!S24,IFERROR('QLD-1'!Y24*'QLD-1'!AB24,0)) | F17: =IF($B17="Actual",'NSW-2'!S24,IFERROR('NSW-2'!Y24*'NSW-2'!AB24,0)) | G17: =IF($B17="Actual",'VIC-2'!S24,IFERROR('VIC-2'!Y24*'VIC-2'!AB24,0)) | H17: =IF($B17="Actual",'QLD-2'!S24,IFERROR('QLD-2'!Y24*'QLD-2'!AB24,0)) | I17: =IF($B17="Actual",'SA-1'!S24,IFERROR('SA-1'!Y24*'SA-1'!AB24,0)) | J17: =IF($B17="Actual",'WA-1'!S24,IFERROR('WA-1'!Y24*'WA-1'!AB24,0)) | K17: =IF($B17="Actual",'IDC-NSW'!S24,IFERROR('IDC-NSW'!Y24*'IDC-NSW'!AB24,0)) | L17: =IF($B17="Actual",'IDC-VIC'!S24,IFERROR('IDC-VIC'!Y24*'IDC-VIC'!AB24,0)) | AJ17: =IF($B17="Actual",C17,IF(Y17<>"",Y17,C17+N(N17))) | AK17: =IF($B17="Actual",D17,IF(Z17<>"",Z17,D17+N(O17))) | AL17: =IF($B17="Actual",E17,IF(AA17<>"",AA17,E17+N(P17))) | AM17: =IF($B17="Actual",F17,IF(AB17<>"",AB17,F17+N(Q17))) | AN17: =IF($B17="Actual",G17,IF(AC17<>"",AC17,G17+N(R17))) | AO17: =IF($B17="Actual",H17,IF(AD17<>"",AD17,H17+N(S17))) | AP17: =IF($B17="Actual",I17,IF(AE17<>"",AE17,I17+N(T17))) | AQ17: =IF($B17="Actual",J17,IF(AF17<>"",AF17,J17+N(U17))) | ... AS17: =IF($B17="Actual",L17,IF(AH17<>"",AH17,L17+N(W17)))
A18: 45962 | B18: =IF(A18<=LastActual,"Actual","Forecast") | C18: =IF($B18="Actual",'NSW-1'!S25,IFERROR('NSW-1'!Y25*'NSW-1'!AB25,0)) | D18: =IF($B18="Actual",'VIC-1'!S25,IFERROR('VIC-1'!Y25*'VIC-1'!AB25,0)) | E18: =IF($B18="Actual",'QLD-1'!S25,IFERROR('QLD-1'!Y25*'QLD-1'!AB25,0)) | F18: =IF($B18="Actual",'NSW-2'!S25,IFERROR('NSW-2'!Y25*'NSW-2'!AB25,0)) | G18: =IF($B18="Actual",'VIC-2'!S25,IFERROR('VIC-2'!Y25*'VIC-2'!AB25,0)) | H18: =IF($B18="Actual",'QLD-2'!S25,IFERROR('QLD-2'!Y25*'QLD-2'!AB25,0)) | I18: =IF($B18="Actual",'SA-1'!S25,IFERROR('SA-1'!Y25*'SA-1'!AB25,0)) | J18: =IF($B18="Actual",'WA-1'!S25,IFERROR('WA-1'!Y25*'WA-1'!AB25,0)) | K18: =IF($B18="Actual",'IDC-NSW'!S25,IFERROR('IDC-NSW'!Y25*'IDC-NSW'!AB25,0)) | L18: =IF($B18="Actual",'IDC-VIC'!S25,IFERROR('IDC-VIC'!Y25*'IDC-VIC'!AB25,0)) | AJ18: =IF($B18="Actual",C18,IF(Y18<>"",Y18,C18+N(N18))) | AK18: =IF($B18="Actual",D18,IF(Z18<>"",Z18,D18+N(O18))) | AL18: =IF($B18="Actual",E18,IF(AA18<>"",AA18,E18+N(P18))) | AM18: =IF($B18="Actual",F18,IF(AB18<>"",AB18,F18+N(Q18))) | AN18: =IF($B18="Actual",G18,IF(AC18<>"",AC18,G18+N(R18))) | AO18: =IF($B18="Actual",H18,IF(AD18<>"",AD18,H18+N(S18))) | AP18: =IF($B18="Actual",I18,IF(AE18<>"",AE18,I18+N(T18))) | AQ18: =IF($B18="Actual",J18,IF(AF18<>"",AF18,J18+N(U18))) | ... AS18: =IF($B18="Actual",L18,IF(AH18<>"",AH18,L18+N(W18)))
A19: 45992 | B19: =IF(A19<=LastActual,"Actual","Forecast") | C19: =IF($B19="Actual",'NSW-1'!S26,IFERROR('NSW-1'!Y26*'NSW-1'!AB26,0)) | D19: =IF($B19="Actual",'VIC-1'!S26,IFERROR('VIC-1'!Y26*'VIC-1'!AB26,0)) | E19: =IF($B19="Actual",'QLD-1'!S26,IFERROR('QLD-1'!Y26*'QLD-1'!AB26,0)) | F19: =IF($B19="Actual",'NSW-2'!S26,IFERROR('NSW-2'!Y26*'NSW-2'!AB26,0)) | G19: =IF($B19="Actual",'VIC-2'!S26,IFERROR('VIC-2'!Y26*'VIC-2'!AB26,0)) | H19: =IF($B19="Actual",'QLD-2'!S26,IFERROR('QLD-2'!Y26*'QLD-2'!AB26,0)) | I19: =IF($B19="Actual",'SA-1'!S26,IFERROR('SA-1'!Y26*'SA-1'!AB26,0)) | J19: =IF($B19="Actual",'WA-1'!S26,IFERROR('WA-1'!Y26*'WA-1'!AB26,0)) | K19: =IF($B19="Actual",'IDC-NSW'!S26,IFERROR('IDC-NSW'!Y26*'IDC-NSW'!AB26,0)) | L19: =IF($B19="Actual",'IDC-VIC'!S26,IFERROR('IDC-VIC'!Y26*'IDC-VIC'!AB26,0)) | AJ19: =IF($B19="Actual",C19,IF(Y19<>"",Y19,C19+N(N19))) | AK19: =IF($B19="Actual",D19,IF(Z19<>"",Z19,D19+N(O19))) | AL19: =IF($B19="Actual",E19,IF(AA19<>"",AA19,E19+N(P19))) | AM19: =IF($B19="Actual",F19,IF(AB19<>"",AB19,F19+N(Q19))) | AN19: =IF($B19="Actual",G19,IF(AC19<>"",AC19,G19+N(R19))) | AO19: =IF($B19="Actual",H19,IF(AD19<>"",AD19,H19+N(S19))) | AP19: =IF($B19="Actual",I19,IF(AE19<>"",AE19,I19+N(T19))) | AQ19: =IF($B19="Actual",J19,IF(AF19<>"",AF19,J19+N(U19))) | ... AS19: =IF($B19="Actual",L19,IF(AH19<>"",AH19,L19+N(W19)))
... A55: 47088 | B55: =IF(A55<=LastActual,"Actual","Forecast") | C55: =IF($B55="Actual",'NSW-1'!S62,IFERROR('NSW-1'!Y62*'NSW-1'!AB62,0)) | D55: =IF($B55="Actual",'VIC-1'!S62,IFERROR('VIC-1'!Y62*'VIC-1'!AB62,0)) | E55: =IF($B55="Actual",'QLD-1'!S62,IFERROR('QLD-1'!Y62*'QLD-1'!AB62,0)) | F55: =IF($B55="Actual",'NSW-2'!S62,IFERROR('NSW-2'!Y62*'NSW-2'!AB62,0)) | G55: =IF($B55="Actual",'VIC-2'!S62,IFERROR('VIC-2'!Y62*'VIC-2'!AB62,0)) | H55: =IF($B55="Actual",'QLD-2'!S62,IFERROR('QLD-2'!Y62*'QLD-2'!AB62,0)) | I55: =IF($B55="Actual",'SA-1'!S62,IFERROR('SA-1'!Y62*'SA-1'!AB62,0)) | J55: =IF($B55="Actual",'WA-1'!S62,IFERROR('WA-1'!Y62*'WA-1'!AB62,0)) | K55: =IF($B55="Actual",'IDC-NSW'!S62,IFERROR('IDC-NSW'!Y62*'IDC-NSW'!AB62,0)) | L55: =IF($B55="Actual",'IDC-VIC'!S62,IFERROR('IDC-VIC'!Y62*'IDC-VIC'!AB62,0)) | AJ55: =IF($B55="Actual",C55,IF(Y55<>"",Y55,C55+N(N55))) | AK55: =IF($B55="Actual",D55,IF(Z55<>"",Z55,D55+N(O55))) | AL55: =IF($B55="Actual",E55,IF(AA55<>"",AA55,E55+N(P55))) | AM55: =IF($B55="Actual",F55,IF(AB55<>"",AB55,F55+N(Q55))) | AN55: =IF($B55="Actual",G55,IF(AC55<>"",AC55,G55+N(R55))) | AO55: =IF($B55="Actual",H55,IF(AD55<>"",AD55,H55+N(S55))) | AP55: =IF($B55="Actual",I55,IF(AE55<>"",AE55,I55+N(T55))) | AQ55: =IF($B55="Actual",J55,IF(AF55<>"",AF55,J55+N(U55))) | ... AS55: =IF($B55="Actual",L55,IF(AH55<>"",AH55,L55+N(W55)))

Sheet CLR
A1: CLR: cost-saving initiatives (placeholder)
A2: Placeholder only. Nothing on this tab feeds the forecast yet.
A4: Initiative | B4: Site | C4: Type | D4: Value | E4: Start month | F4: Ramp-up months | G4: End month | H4: Active | I4: Owner / notes

Sheet Holidays
A1: Date | B1: Holiday | C1: State | E1: Generated by rule. Add, remove or move rows freely; the Calendar tab counts them by state and month.
A2: 45658 | B2: New Year's Day | C2: NSW
A3: 45684 | B3: Australia Day | C3: NSW
A4: 45765 | B4: Good Friday | C4: NSW
A5: 45766 | B5: Easter Saturday | C5: NSW
A6: 45767 | B6: Easter Sunday | C6: NSW
A7: 45768 | B7: Easter Monday | C7: NSW
A8: 45772 | B8: Anzac Day | C8: NSW
A9: 45817 | B9: King's Birthday | C9: NSW
A10: 45936 | B10: Labour Day | C10: NSW
A11: 46016 | B11: Christmas Day | C11: NSW
A12: 46017 | B12: Boxing Day | C12: NSW
A13: 46023 | B13: New Year's Day | C13: NSW
... A256: 47113 | B256: Boxing Day | C256: WA

Sheet Calendar
A1: Calendar: public holidays, PH cost factor, wage index
A2: PH factor = average cost per hour in the month vs a month with no public holidays.
C3: Public holidays (count) | H3: PH cost factor
A4: Month | B4: Days | C4: PH NSW | D4: PH VIC | E4: PH QLD | F4: PH SA | G4: PH WA | H4: NSW | I4: VIC | J4: QLD | K4: SA | L4: WA | M4: Wage index
A5: 45658 | B5: =DAY(EOMONTH(A5,0)) | C5: =COUNTIFS(Holidays!$A$2:$A$1000,">="&$A5,Holidays!$A$2:$A$1000,"<="&EOMONTH($A5,0),Holidays!$C$2:$C$1000,"NSW") | D5: =COUNTIFS(Holidays!$A$2:$A$1000,">="&$A5,Holidays!$A$2:$A$1000,"<="&EOMONTH($A5,0),Holidays!$C$2:$C$1000,"VIC") | E5: =COUNTIFS(Holidays!$A$2:$A$1000,">="&$A5,Holidays!$A$2:$A$1000,"<="&EOMONTH($A5,0),Holidays!$C$2:$C$1000,"QLD") | F5: =COUNTIFS(Holidays!$A$2:$A$1000,">="&$A5,Holidays!$A$2:$A$1000,"<="&EOMONTH($A5,0),Holidays!$C$2:$C$1000,"SA") | G5: =COUNTIFS(Holidays!$A$2:$A$1000,">="&$A5,Holidays!$A$2:$A$1000,"<="&EOMONTH($A5,0),Holidays!$C$2:$C$1000,"WA") | H5: =($B5-C5+C5*PH_Roster*(1+PH_Loading))/($B5-C5+C5*PH_Roster) | I5: =($B5-D5+D5*PH_Roster*(1+PH_Loading))/($B5-D5+D5*PH_Roster) | J5: =($B5-E5+E5*PH_Roster*(1+PH_Loading))/($B5-E5+E5*PH_Roster) | K5: =($B5-F5+F5*PH_Roster*(1+PH_Loading))/($B5-F5+F5*PH_Roster) | L5: =($B5-G5+G5*PH_Roster*(1+PH_Loading))/($B5-G5+G5*PH_Roster) | M5: =EXP(SUMPRODUCT((WageDates<=$A5)*(WageDates<>"")*LN(1+WageRates)))
A6: 45689 | B6: =DAY(EOMONTH(A6,0)) | C6: =COUNTIFS(Holidays!$A$2:$A$1000,">="&$A6,Holidays!$A$2:$A$1000,"<="&EOMONTH($A6,0),Holidays!$C$2:$C$1000,"NSW") | D6: =COUNTIFS(Holidays!$A$2:$A$1000,">="&$A6,Holidays!$A$2:$A$1000,"<="&EOMONTH($A6,0),Holidays!$C$2:$C$1000,"VIC") | E6: =COUNTIFS(Holidays!$A$2:$A$1000,">="&$A6,Holidays!$A$2:$A$1000,"<="&EOMONTH($A6,0),Holidays!$C$2:$C$1000,"QLD") | F6: =COUNTIFS(Holidays!$A$2:$A$1000,">="&$A6,Holidays!$A$2:$A$1000,"<="&EOMONTH($A6,0),Holidays!$C$2:$C$1000,"SA") | G6: =COUNTIFS(Holidays!$A$2:$A$1000,">="&$A6,Holidays!$A$2:$A$1000,"<="&EOMONTH($A6,0),Holidays!$C$2:$C$1000,"WA") | H6: =($B6-C6+C6*PH_Roster*(1+PH_Loading))/($B6-C6+C6*PH_Roster) | I6: =($B6-D6+D6*PH_Roster*(1+PH_Loading))/($B6-D6+D6*PH_Roster) | J6: =($B6-E6+E6*PH_Roster*(1+PH_Loading))/($B6-E6+E6*PH_Roster) | K6: =($B6-F6+F6*PH_Roster*(1+PH_Loading))/($B6-F6+F6*PH_Roster) | L6: =($B6-G6+G6*PH_Roster*(1+PH_Loading))/($B6-G6+G6*PH_Roster) | M6: =EXP(SUMPRODUCT((WageDates<=$A6)*(WageDates<>"")*LN(1+WageRates)))
A7: 45717 | B7: =DAY(EOMONTH(A7,0)) | C7: =COUNTIFS(Holidays!$A$2:$A$1000,">="&$A7,Holidays!$A$2:$A$1000,"<="&EOMONTH($A7,0),Holidays!$C$2:$C$1000,"NSW") | D7: =COUNTIFS(Holidays!$A$2:$A$1000,">="&$A7,Holidays!$A$2:$A$1000,"<="&EOMONTH($A7,0),Holidays!$C$2:$C$1000,"VIC") | E7: =COUNTIFS(Holidays!$A$2:$A$1000,">="&$A7,Holidays!$A$2:$A$1000,"<="&EOMONTH($A7,0),Holidays!$C$2:$C$1000,"QLD") | F7: =COUNTIFS(Holidays!$A$2:$A$1000,">="&$A7,Holidays!$A$2:$A$1000,"<="&EOMONTH($A7,0),Holidays!$C$2:$C$1000,"SA") | G7: =COUNTIFS(Holidays!$A$2:$A$1000,">="&$A7,Holidays!$A$2:$A$1000,"<="&EOMONTH($A7,0),Holidays!$C$2:$C$1000,"WA") | H7: =($B7-C7+C7*PH_Roster*(1+PH_Loading))/($B7-C7+C7*PH_Roster) | I7: =($B7-D7+D7*PH_Roster*(1+PH_Loading))/($B7-D7+D7*PH_Roster) | J7: =($B7-E7+E7*PH_Roster*(1+PH_Loading))/($B7-E7+E7*PH_Roster) | K7: =($B7-F7+F7*PH_Roster*(1+PH_Loading))/($B7-F7+F7*PH_Roster) | L7: =($B7-G7+G7*PH_Roster*(1+PH_Loading))/($B7-G7+G7*PH_Roster) | M7: =EXP(SUMPRODUCT((WageDates<=$A7)*(WageDates<>"")*LN(1+WageRates)))
A8: 45748 | B8: =DAY(EOMONTH(A8,0)) | C8: =COUNTIFS(Holidays!$A$2:$A$1000,">="&$A8,Holidays!$A$2:$A$1000,"<="&EOMONTH($A8,0),Holidays!$C$2:$C$1000,"NSW") | D8: =COUNTIFS(Holidays!$A$2:$A$1000,">="&$A8,Holidays!$A$2:$A$1000,"<="&EOMONTH($A8,0),Holidays!$C$2:$C$1000,"VIC") | E8: =COUNTIFS(Holidays!$A$2:$A$1000,">="&$A8,Holidays!$A$2:$A$1000,"<="&EOMONTH($A8,0),Holidays!$C$2:$C$1000,"QLD") | F8: =COUNTIFS(Holidays!$A$2:$A$1000,">="&$A8,Holidays!$A$2:$A$1000,"<="&EOMONTH($A8,0),Holidays!$C$2:$C$1000,"SA") | G8: =COUNTIFS(Holidays!$A$2:$A$1000,">="&$A8,Holidays!$A$2:$A$1000,"<="&EOMONTH($A8,0),Holidays!$C$2:$C$1000,"WA") | H8: =($B8-C8+C8*PH_Roster*(1+PH_Loading))/($B8-C8+C8*PH_Roster) | I8: =($B8-D8+D8*PH_Roster*(1+PH_Loading))/($B8-D8+D8*PH_Roster) | J8: =($B8-E8+E8*PH_Roster*(1+PH_Loading))/($B8-E8+E8*PH_Roster) | K8: =($B8-F8+F8*PH_Roster*(1+PH_Loading))/($B8-F8+F8*PH_Roster) | L8: =($B8-G8+G8*PH_Roster*(1+PH_Loading))/($B8-G8+G8*PH_Roster) | M8: =EXP(SUMPRODUCT((WageDates<=$A8)*(WageDates<>"")*LN(1+WageRates)))
A9: 45778 | B9: =DAY(EOMONTH(A9,0)) | C9: =COUNTIFS(Holidays!$A$2:$A$1000,">="&$A9,Holidays!$A$2:$A$1000,"<="&EOMONTH($A9,0),Holidays!$C$2:$C$1000,"NSW") | D9: =COUNTIFS(Holidays!$A$2:$A$1000,">="&$A9,Holidays!$A$2:$A$1000,"<="&EOMONTH($A9,0),Holidays!$C$2:$C$1000,"VIC") | E9: =COUNTIFS(Holidays!$A$2:$A$1000,">="&$A9,Holidays!$A$2:$A$1000,"<="&EOMONTH($A9,0),Holidays!$C$2:$C$1000,"QLD") | F9: =COUNTIFS(Holidays!$A$2:$A$1000,">="&$A9,Holidays!$A$2:$A$1000,"<="&EOMONTH($A9,0),Holidays!$C$2:$C$1000,"SA") | G9: =COUNTIFS(Holidays!$A$2:$A$1000,">="&$A9,Holidays!$A$2:$A$1000,"<="&EOMONTH($A9,0),Holidays!$C$2:$C$1000,"WA") | H9: =($B9-C9+C9*PH_Roster*(1+PH_Loading))/($B9-C9+C9*PH_Roster) | I9: =($B9-D9+D9*PH_Roster*(1+PH_Loading))/($B9-D9+D9*PH_Roster) | J9: =($B9-E9+E9*PH_Roster*(1+PH_Loading))/($B9-E9+E9*PH_Roster) | K9: =($B9-F9+F9*PH_Roster*(1+PH_Loading))/($B9-F9+F9*PH_Roster) | L9: =($B9-G9+G9*PH_Roster*(1+PH_Loading))/($B9-G9+G9*PH_Roster) | M9: =EXP(SUMPRODUCT((WageDates<=$A9)*(WageDates<>"")*LN(1+WageRates)))
A10: 45809 | B10: =DAY(EOMONTH(A10,0)) | C10: =COUNTIFS(Holidays!$A$2:$A$1000,">="&$A10,Holidays!$A$2:$A$1000,"<="&EOMONTH($A10,0),Holidays!$C$2:$C$1000,"NSW") | D10: =COUNTIFS(Holidays!$A$2:$A$1000,">="&$A10,Holidays!$A$2:$A$1000,"<="&EOMONTH($A10,0),Holidays!$C$2:$C$1000,"VIC") | E10: =COUNTIFS(Holidays!$A$2:$A$1000,">="&$A10,Holidays!$A$2:$A$1000,"<="&EOMONTH($A10,0),Holidays!$C$2:$C$1000,"QLD") | F10: =COUNTIFS(Holidays!$A$2:$A$1000,">="&$A10,Holidays!$A$2:$A$1000,"<="&EOMONTH($A10,0),Holidays!$C$2:$C$1000,"SA") | G10: =COUNTIFS(Holidays!$A$2:$A$1000,">="&$A10,Holidays!$A$2:$A$1000,"<="&EOMONTH($A10,0),Holidays!$C$2:$C$1000,"WA") | H10: =($B10-C10+C10*PH_Roster*(1+PH_Loading))/($B10-C10+C10*PH_Roster) | I10: =($B10-D10+D10*PH_Roster*(1+PH_Loading))/($B10-D10+D10*PH_Roster) | J10: =($B10-E10+E10*PH_Roster*(1+PH_Loading))/($B10-E10+E10*PH_Roster) | K10: =($B10-F10+F10*PH_Roster*(1+PH_Loading))/($B10-F10+F10*PH_Roster) | L10: =($B10-G10+G10*PH_Roster*(1+PH_Loading))/($B10-G10+G10*PH_Roster) | M10: =EXP(SUMPRODUCT((WageDates<=$A10)*(WageDates<>"")*LN(1+WageRates)))
A11: 45839 | B11: =DAY(EOMONTH(A11,0)) | C11: =COUNTIFS(Holidays!$A$2:$A$1000,">="&$A11,Holidays!$A$2:$A$1000,"<="&EOMONTH($A11,0),Holidays!$C$2:$C$1000,"NSW") | D11: =COUNTIFS(Holidays!$A$2:$A$1000,">="&$A11,Holidays!$A$2:$A$1000,"<="&EOMONTH($A11,0),Holidays!$C$2:$C$1000,"VIC") | E11: =COUNTIFS(Holidays!$A$2:$A$1000,">="&$A11,Holidays!$A$2:$A$1000,"<="&EOMONTH($A11,0),Holidays!$C$2:$C$1000,"QLD") | F11: =COUNTIFS(Holidays!$A$2:$A$1000,">="&$A11,Holidays!$A$2:$A$1000,"<="&EOMONTH($A11,0),Holidays!$C$2:$C$1000,"SA") | G11: =COUNTIFS(Holidays!$A$2:$A$1000,">="&$A11,Holidays!$A$2:$A$1000,"<="&EOMONTH($A11,0),Holidays!$C$2:$C$1000,"WA") | H11: =($B11-C11+C11*PH_Roster*(1+PH_Loading))/($B11-C11+C11*PH_Roster) | I11: =($B11-D11+D11*PH_Roster*(1+PH_Loading))/($B11-D11+D11*PH_Roster) | J11: =($B11-E11+E11*PH_Roster*(1+PH_Loading))/($B11-E11+E11*PH_Roster) | K11: =($B11-F11+F11*PH_Roster*(1+PH_Loading))/($B11-F11+F11*PH_Roster) | L11: =($B11-G11+G11*PH_Roster*(1+PH_Loading))/($B11-G11+G11*PH_Roster) | M11: =EXP(SUMPRODUCT((WageDates<=$A11)*(WageDates<>"")*LN(1+WageRates)))
A12: 45870 | B12: =DAY(EOMONTH(A12,0)) | C12: =COUNTIFS(Holidays!$A$2:$A$1000,">="&$A12,Holidays!$A$2:$A$1000,"<="&EOMONTH($A12,0),Holidays!$C$2:$C$1000,"NSW") | D12: =COUNTIFS(Holidays!$A$2:$A$1000,">="&$A12,Holidays!$A$2:$A$1000,"<="&EOMONTH($A12,0),Holidays!$C$2:$C$1000,"VIC") | E12: =COUNTIFS(Holidays!$A$2:$A$1000,">="&$A12,Holidays!$A$2:$A$1000,"<="&EOMONTH($A12,0),Holidays!$C$2:$C$1000,"QLD") | F12: =COUNTIFS(Holidays!$A$2:$A$1000,">="&$A12,Holidays!$A$2:$A$1000,"<="&EOMONTH($A12,0),Holidays!$C$2:$C$1000,"SA") | G12: =COUNTIFS(Holidays!$A$2:$A$1000,">="&$A12,Holidays!$A$2:$A$1000,"<="&EOMONTH($A12,0),Holidays!$C$2:$C$1000,"WA") | H12: =($B12-C12+C12*PH_Roster*(1+PH_Loading))/($B12-C12+C12*PH_Roster) | I12: =($B12-D12+D12*PH_Roster*(1+PH_Loading))/($B12-D12+D12*PH_Roster) | J12: =($B12-E12+E12*PH_Roster*(1+PH_Loading))/($B12-E12+E12*PH_Roster) | K12: =($B12-F12+F12*PH_Roster*(1+PH_Loading))/($B12-F12+F12*PH_Roster) | L12: =($B12-G12+G12*PH_Roster*(1+PH_Loading))/($B12-G12+G12*PH_Roster) | M12: =EXP(SUMPRODUCT((WageDates<=$A12)*(WageDates<>"")*LN(1+WageRates)))
A13: 45901 | B13: =DAY(EOMONTH(A13,0)) | C13: =COUNTIFS(Holidays!$A$2:$A$1000,">="&$A13,Holidays!$A$2:$A$1000,"<="&EOMONTH($A13,0),Holidays!$C$2:$C$1000,"NSW") | D13: =COUNTIFS(Holidays!$A$2:$A$1000,">="&$A13,Holidays!$A$2:$A$1000,"<="&EOMONTH($A13,0),Holidays!$C$2:$C$1000,"VIC") | E13: =COUNTIFS(Holidays!$A$2:$A$1000,">="&$A13,Holidays!$A$2:$A$1000,"<="&EOMONTH($A13,0),Holidays!$C$2:$C$1000,"QLD") | F13: =COUNTIFS(Holidays!$A$2:$A$1000,">="&$A13,Holidays!$A$2:$A$1000,"<="&EOMONTH($A13,0),Holidays!$C$2:$C$1000,"SA") | G13: =COUNTIFS(Holidays!$A$2:$A$1000,">="&$A13,Holidays!$A$2:$A$1000,"<="&EOMONTH($A13,0),Holidays!$C$2:$C$1000,"WA") | H13: =($B13-C13+C13*PH_Roster*(1+PH_Loading))/($B13-C13+C13*PH_Roster) | I13: =($B13-D13+D13*PH_Roster*(1+PH_Loading))/($B13-D13+D13*PH_Roster) | J13: =($B13-E13+E13*PH_Roster*(1+PH_Loading))/($B13-E13+E13*PH_Roster) | K13: =($B13-F13+F13*PH_Roster*(1+PH_Loading))/($B13-F13+F13*PH_Roster) | L13: =($B13-G13+G13*PH_Roster*(1+PH_Loading))/($B13-G13+G13*PH_Roster) | M13: =EXP(SUMPRODUCT((WageDates<=$A13)*(WageDates<>"")*LN(1+WageRates)))
A14: 45931 | B14: =DAY(EOMONTH(A14,0)) | C14: =COUNTIFS(Holidays!$A$2:$A$1000,">="&$A14,Holidays!$A$2:$A$1000,"<="&EOMONTH($A14,0),Holidays!$C$2:$C$1000,"NSW") | D14: =COUNTIFS(Holidays!$A$2:$A$1000,">="&$A14,Holidays!$A$2:$A$1000,"<="&EOMONTH($A14,0),Holidays!$C$2:$C$1000,"VIC") | E14: =COUNTIFS(Holidays!$A$2:$A$1000,">="&$A14,Holidays!$A$2:$A$1000,"<="&EOMONTH($A14,0),Holidays!$C$2:$C$1000,"QLD") | F14: =COUNTIFS(Holidays!$A$2:$A$1000,">="&$A14,Holidays!$A$2:$A$1000,"<="&EOMONTH($A14,0),Holidays!$C$2:$C$1000,"SA") | G14: =COUNTIFS(Holidays!$A$2:$A$1000,">="&$A14,Holidays!$A$2:$A$1000,"<="&EOMONTH($A14,0),Holidays!$C$2:$C$1000,"WA") | H14: =($B14-C14+C14*PH_Roster*(1+PH_Loading))/($B14-C14+C14*PH_Roster) | I14: =($B14-D14+D14*PH_Roster*(1+PH_Loading))/($B14-D14+D14*PH_Roster) | J14: =($B14-E14+E14*PH_Roster*(1+PH_Loading))/($B14-E14+E14*PH_Roster) | K14: =($B14-F14+F14*PH_Roster*(1+PH_Loading))/($B14-F14+F14*PH_Roster) | L14: =($B14-G14+G14*PH_Roster*(1+PH_Loading))/($B14-G14+G14*PH_Roster) | M14: =EXP(SUMPRODUCT((WageDates<=$A14)*(WageDates<>"")*LN(1+WageRates)))
A15: 45962 | B15: =DAY(EOMONTH(A15,0)) | C15: =COUNTIFS(Holidays!$A$2:$A$1000,">="&$A15,Holidays!$A$2:$A$1000,"<="&EOMONTH($A15,0),Holidays!$C$2:$C$1000,"NSW") | D15: =COUNTIFS(Holidays!$A$2:$A$1000,">="&$A15,Holidays!$A$2:$A$1000,"<="&EOMONTH($A15,0),Holidays!$C$2:$C$1000,"VIC") | E15: =COUNTIFS(Holidays!$A$2:$A$1000,">="&$A15,Holidays!$A$2:$A$1000,"<="&EOMONTH($A15,0),Holidays!$C$2:$C$1000,"QLD") | F15: =COUNTIFS(Holidays!$A$2:$A$1000,">="&$A15,Holidays!$A$2:$A$1000,"<="&EOMONTH($A15,0),Holidays!$C$2:$C$1000,"SA") | G15: =COUNTIFS(Holidays!$A$2:$A$1000,">="&$A15,Holidays!$A$2:$A$1000,"<="&EOMONTH($A15,0),Holidays!$C$2:$C$1000,"WA") | H15: =($B15-C15+C15*PH_Roster*(1+PH_Loading))/($B15-C15+C15*PH_Roster) | I15: =($B15-D15+D15*PH_Roster*(1+PH_Loading))/($B15-D15+D15*PH_Roster) | J15: =($B15-E15+E15*PH_Roster*(1+PH_Loading))/($B15-E15+E15*PH_Roster) | K15: =($B15-F15+F15*PH_Roster*(1+PH_Loading))/($B15-F15+F15*PH_Roster) | L15: =($B15-G15+G15*PH_Roster*(1+PH_Loading))/($B15-G15+G15*PH_Roster) | M15: =EXP(SUMPRODUCT((WageDates<=$A15)*(WageDates<>"")*LN(1+WageRates)))
A16: 45992 | B16: =DAY(EOMONTH(A16,0)) | C16: =COUNTIFS(Holidays!$A$2:$A$1000,">="&$A16,Holidays!$A$2:$A$1000,"<="&EOMONTH($A16,0),Holidays!$C$2:$C$1000,"NSW") | D16: =COUNTIFS(Holidays!$A$2:$A$1000,">="&$A16,Holidays!$A$2:$A$1000,"<="&EOMONTH($A16,0),Holidays!$C$2:$C$1000,"VIC") | E16: =COUNTIFS(Holidays!$A$2:$A$1000,">="&$A16,Holidays!$A$2:$A$1000,"<="&EOMONTH($A16,0),Holidays!$C$2:$C$1000,"QLD") | F16: =COUNTIFS(Holidays!$A$2:$A$1000,">="&$A16,Holidays!$A$2:$A$1000,"<="&EOMONTH($A16,0),Holidays!$C$2:$C$1000,"SA") | G16: =COUNTIFS(Holidays!$A$2:$A$1000,">="&$A16,Holidays!$A$2:$A$1000,"<="&EOMONTH($A16,0),Holidays!$C$2:$C$1000,"WA") | H16: =($B16-C16+C16*PH_Roster*(1+PH_Loading))/($B16-C16+C16*PH_Roster) | I16: =($B16-D16+D16*PH_Roster*(1+PH_Loading))/($B16-D16+D16*PH_Roster) | J16: =($B16-E16+E16*PH_Roster*(1+PH_Loading))/($B16-E16+E16*PH_Roster) | K16: =($B16-F16+F16*PH_Roster*(1+PH_Loading))/($B16-F16+F16*PH_Roster) | L16: =($B16-G16+G16*PH_Roster*(1+PH_Loading))/($B16-G16+G16*PH_Roster) | M16: =EXP(SUMPRODUCT((WageDates<=$A16)*(WageDates<>"")*LN(1+WageRates)))
... A52: 47088 | B52: =DAY(EOMONTH(A52,0)) | C52: =COUNTIFS(Holidays!$A$2:$A$1000,">="&$A52,Holidays!$A$2:$A$1000,"<="&EOMONTH($A52,0),Holidays!$C$2:$C$1000,"NSW") | D52: =COUNTIFS(Holidays!$A$2:$A$1000,">="&$A52,Holidays!$A$2:$A$1000,"<="&EOMONTH($A52,0),Holidays!$C$2:$C$1000,"VIC") | E52: =COUNTIFS(Holidays!$A$2:$A$1000,">="&$A52,Holidays!$A$2:$A$1000,"<="&EOMONTH($A52,0),Holidays!$C$2:$C$1000,"QLD") | F52: =COUNTIFS(Holidays!$A$2:$A$1000,">="&$A52,Holidays!$A$2:$A$1000,"<="&EOMONTH($A52,0),Holidays!$C$2:$C$1000,"SA") | G52: =COUNTIFS(Holidays!$A$2:$A$1000,">="&$A52,Holidays!$A$2:$A$1000,"<="&EOMONTH($A52,0),Holidays!$C$2:$C$1000,"WA") | H52: =($B52-C52+C52*PH_Roster*(1+PH_Loading))/($B52-C52+C52*PH_Roster) | I52: =($B52-D52+D52*PH_Roster*(1+PH_Loading))/($B52-D52+D52*PH_Roster) | J52: =($B52-E52+E52*PH_Roster*(1+PH_Loading))/($B52-E52+E52*PH_Roster) | K52: =($B52-F52+F52*PH_Roster*(1+PH_Loading))/($B52-F52+F52*PH_Roster) | L52: =($B52-G52+G52*PH_Roster*(1+PH_Loading))/($B52-G52+G52*PH_Roster) | M52: =EXP(SUMPRODUCT((WageDates<=$A52)*(WageDates<>"")*LN(1+WageRates)))

Sheet Checks
A1: Checks
A3: Overall | B3: =IF(COUNTIF(D6:D80,"ERROR")=0,"ALL CHECKS OK","CHECK ERRORS") | C3: =COUNTIF(D6:D80,"WARN")&" warning(s)"
A5: Check | B5: Value | C5: Expected | D5: Result
A6: =Inputs!$A$36&": actual rows in Data_Actuals (one per month)" | B6: =COUNTIFS(Data_Actuals!$B$2:$B$5000,Inputs!$A$36,Data_Actuals!$A$2:$A$5000,"<="&LastActual) | C6: =(YEAR(LastActual)-2025)*12+MONTH(LastActual) | D6: =IF(ABS(B6-C6)<=MAX(1,ABS(C6)*0.000001),"OK","ERROR")
A7: =Inputs!$A$37&": actual rows in Data_Actuals (one per month)" | B7: =COUNTIFS(Data_Actuals!$B$2:$B$5000,Inputs!$A$37,Data_Actuals!$A$2:$A$5000,"<="&LastActual) | C7: =(YEAR(LastActual)-2025)*12+MONTH(LastActual) | D7: =IF(ABS(B7-C7)<=MAX(1,ABS(C7)*0.000001),"OK","ERROR")
A8: =Inputs!$A$38&": actual rows in Data_Actuals (one per month)" | B8: =COUNTIFS(Data_Actuals!$B$2:$B$5000,Inputs!$A$38,Data_Actuals!$A$2:$A$5000,"<="&LastActual) | C8: =(YEAR(LastActual)-2025)*12+MONTH(LastActual) | D8: =IF(ABS(B8-C8)<=MAX(1,ABS(C8)*0.000001),"OK","ERROR")
A9: =Inputs!$A$39&": actual rows in Data_Actuals (one per month)" | B9: =COUNTIFS(Data_Actuals!$B$2:$B$5000,Inputs!$A$39,Data_Actuals!$A$2:$A$5000,"<="&LastActual) | C9: =(YEAR(LastActual)-2025)*12+MONTH(LastActual) | D9: =IF(ABS(B9-C9)<=MAX(1,ABS(C9)*0.000001),"OK","ERROR")
A10: =Inputs!$A$40&": actual rows in Data_Actuals (one per month)" | B10: =COUNTIFS(Data_Actuals!$B$2:$B$5000,Inputs!$A$40,Data_Actuals!$A$2:$A$5000,"<="&LastActual) | C10: =(YEAR(LastActual)-2025)*12+MONTH(LastActual) | D10: =IF(ABS(B10-C10)<=MAX(1,ABS(C10)*0.000001),"OK","ERROR")
A11: =Inputs!$A$41&": actual rows in Data_Actuals (one per month)" | B11: =COUNTIFS(Data_Actuals!$B$2:$B$5000,Inputs!$A$41,Data_Actuals!$A$2:$A$5000,"<="&LastActual) | C11: =(YEAR(LastActual)-2025)*12+MONTH(LastActual) | D11: =IF(ABS(B11-C11)<=MAX(1,ABS(C11)*0.000001),"OK","ERROR")
A12: =Inputs!$A$42&": actual rows in Data_Actuals (one per month)" | B12: =COUNTIFS(Data_Actuals!$B$2:$B$5000,Inputs!$A$42,Data_Actuals!$A$2:$A$5000,"<="&LastActual) | C12: =(YEAR(LastActual)-2025)*12+MONTH(LastActual) | D12: =IF(ABS(B12-C12)<=MAX(1,ABS(C12)*0.000001),"OK","ERROR")
A13: =Inputs!$A$43&": actual rows in Data_Actuals (one per month)" | B13: =COUNTIFS(Data_Actuals!$B$2:$B$5000,Inputs!$A$43,Data_Actuals!$A$2:$A$5000,"<="&LastActual) | C13: =(YEAR(LastActual)-2025)*12+MONTH(LastActual) | D13: =IF(ABS(B13-C13)<=MAX(1,ABS(C13)*0.000001),"OK","ERROR")
A14: =Inputs!$A$44&": actual rows in Data_Actuals (one per month)" | B14: =COUNTIFS(Data_Actuals!$B$2:$B$5000,Inputs!$A$44,Data_Actuals!$A$2:$A$5000,"<="&LastActual) | C14: =(YEAR(LastActual)-2025)*12+MONTH(LastActual) | D14: =IF(ABS(B14-C14)<=MAX(1,ABS(C14)*0.000001),"OK","ERROR")
A15: =Inputs!$A$45&": actual rows in Data_Actuals (one per month)" | B15: =COUNTIFS(Data_Actuals!$B$2:$B$5000,Inputs!$A$45,Data_Actuals!$A$2:$A$5000,"<="&LastActual) | C15: =(YEAR(LastActual)-2025)*12+MONTH(LastActual) | D15: =IF(ABS(B15-C15)<=MAX(1,ABS(C15)*0.000001),"OK","ERROR")
A16: =Inputs!$A$36&": plan payroll % present for every forecast month" | B16: =COUNTIFS(Plan_Inputs!$B$2:$B$5000,Inputs!$A$36,Plan_Inputs!$A$2:$A$5000,">"&LastActual,Plan_Inputs!$D$2:$D$5000,">0") | C16: =(2028-YEAR(LastActual))*12+12-MONTH(LastActual) | D16: =IF(ABS(B16-C16)<=MAX(1,ABS(C16)*0.000001),"OK","ERROR")
A17: =Inputs!$A$37&": plan payroll % present for every forecast month" | B17: =COUNTIFS(Plan_Inputs!$B$2:$B$5000,Inputs!$A$37,Plan_Inputs!$A$2:$A$5000,">"&LastActual,Plan_Inputs!$D$2:$D$5000,">0") | C17: =(2028-YEAR(LastActual))*12+12-MONTH(LastActual) | D17: =IF(ABS(B17-C17)<=MAX(1,ABS(C17)*0.000001),"OK","ERROR")
A18: =Inputs!$A$38&": plan payroll % present for every forecast month" | B18: =COUNTIFS(Plan_Inputs!$B$2:$B$5000,Inputs!$A$38,Plan_Inputs!$A$2:$A$5000,">"&LastActual,Plan_Inputs!$D$2:$D$5000,">0") | C18: =(2028-YEAR(LastActual))*12+12-MONTH(LastActual) | D18: =IF(ABS(B18-C18)<=MAX(1,ABS(C18)*0.000001),"OK","ERROR")
A19: =Inputs!$A$39&": plan payroll % present for every forecast month" | B19: =COUNTIFS(Plan_Inputs!$B$2:$B$5000,Inputs!$A$39,Plan_Inputs!$A$2:$A$5000,">"&LastActual,Plan_Inputs!$D$2:$D$5000,">0") | C19: =(2028-YEAR(LastActual))*12+12-MONTH(LastActual) | D19: =IF(ABS(B19-C19)<=MAX(1,ABS(C19)*0.000001),"OK","ERROR")
A20: =Inputs!$A$40&": plan payroll % present for every forecast month" | B20: =COUNTIFS(Plan_Inputs!$B$2:$B$5000,Inputs!$A$40,Plan_Inputs!$A$2:$A$5000,">"&LastActual,Plan_Inputs!$D$2:$D$5000,">0") | C20: =(2028-YEAR(LastActual))*12+12-MONTH(LastActual) | D20: =IF(ABS(B20-C20)<=MAX(1,ABS(C20)*0.000001),"OK","ERROR")
A21: =Inputs!$A$41&": plan payroll % present for every forecast month" | B21: =COUNTIFS(Plan_Inputs!$B$2:$B$5000,Inputs!$A$41,Plan_Inputs!$A$2:$A$5000,">"&LastActual,Plan_Inputs!$D$2:$D$5000,">0") | C21: =(2028-YEAR(LastActual))*12+12-MONTH(LastActual) | D21: =IF(ABS(B21-C21)<=MAX(1,ABS(C21)*0.000001),"OK","ERROR")
A22: =Inputs!$A$42&": plan payroll % present for every forecast month" | B22: =COUNTIFS(Plan_Inputs!$B$2:$B$5000,Inputs!$A$42,Plan_Inputs!$A$2:$A$5000,">"&LastActual,Plan_Inputs!$D$2:$D$5000,">0") | C22: =(2028-YEAR(LastActual))*12+12-MONTH(LastActual) | D22: =IF(ABS(B22-C22)<=MAX(1,ABS(C22)*0.000001),"OK","ERROR")
A23: =Inputs!$A$43&": plan payroll % present for every forecast month" | B23: =COUNTIFS(Plan_Inputs!$B$2:$B$5000,Inputs!$A$43,Plan_Inputs!$A$2:$A$5000,">"&LastActual,Plan_Inputs!$D$2:$D$5000,">0") | C23: =(2028-YEAR(LastActual))*12+12-MONTH(LastActual) | D23: =IF(ABS(B23-C23)<=MAX(1,ABS(C23)*0.000001),"OK","ERROR")
A24: =Inputs!$A$44&": plan payroll % present for every forecast month" | B24: =COUNTIFS(Plan_Inputs!$B$2:$B$5000,Inputs!$A$44,Plan_Inputs!$A$2:$A$5000,">"&LastActual,Plan_Inputs!$D$2:$D$5000,">0") | C24: =(2028-YEAR(LastActual))*12+12-MONTH(LastActual) | D24: =IF(ABS(B24-C24)<=MAX(1,ABS(C24)*0.000001),"OK","ERROR")
A25: =Inputs!$A$45&": plan payroll % present for every forecast month" | B25: =COUNTIFS(Plan_Inputs!$B$2:$B$5000,Inputs!$A$45,Plan_Inputs!$A$2:$A$5000,">"&LastActual,Plan_Inputs!$D$2:$D$5000,">0") | C25: =(2028-YEAR(LastActual))*12+12-MONTH(LastActual) | D25: =IF(ABS(B25-C25)<=MAX(1,ABS(C25)*0.000001),"OK","ERROR")
A26: Unknown site codes in Data_Actuals | B26: =SUMPRODUCT((Data_Actuals!$B$2:$B$5000<>"")*(COUNTIF(SiteCodes,Data_Actuals!$B$2:$B$5000)=0)) | C26: =0 | D26: =IF(ABS(B26-C26)<=MAX(1,ABS(C26)*0.000001),"OK","ERROR")
A27: At least 12 actual months (same month last year needs them) | B27: =(YEAR(LastActual)-2025)*12+MONTH(LastActual) | C27: =12 | D27: =IF(B27>=C27,"OK","ERROR")
A28: National sales = sum of 8 regions (IDCs excluded) | B28: =SUM(National!E15:E62) | C28: =SUM('NSW-1'!E15:E62)+SUM('VIC-1'!E15:E62)+SUM('QLD-1'!E15:E62)+SUM('NSW-2'!E15:E62)+SUM('VIC-2'!E15:E62)+SUM('QLD-2'!E15:E62)+SUM('SA-1'!E15:E62)+SUM('WA-1'!E15:E62) | D28: =IF(ABS(B28-C28)<=MAX(1,ABS(C28)*0.000001),"OK","ERROR")
A29: National total payroll = sum of all 10 sites | B29: =SUM(National!J15:J62) | C29: =SUM('NSW-1'!J15:J62)+SUM('VIC-1'!J15:J62)+SUM('QLD-1'!J15:J62)+SUM('NSW-2'!J15:J62)+SUM('VIC-2'!J15:J62)+SUM('QLD-2'!J15:J62)+SUM('SA-1'!J15:J62)+SUM('WA-1'!J15:J62)+SUM('IDC-NSW'!J15:J62)+SUM('IDC-VIC'!J15:J62) | D29: =IF(ABS(B29-C29)<=MAX(1,ABS(C29)*0.000001),"OK","ERROR")
A30: Staff + leadership = total payroll (national, all months) | B30: =SUM(National!H15:I62) | C30: =SUM(National!J15:J62) | D30: =IF(ABS(B30-C30)<=MAX(1,ABS(C30)*0.000001),"OK","ERROR")
A31: Cases_Forecast: adjustments typed in actual months (ignored) | B31: =SUMPRODUCT((Cases_Forecast!$B$8:$B$55="Actual")*(Cases_Forecast!$N$8:$W$55<>"")) | C31: =0 | D31: =IF(B31=C31,"OK","WARN")
A32: Cases_Forecast: overrides typed in actual months (ignored) | B32: =SUMPRODUCT((Cases_Forecast!$B$8:$B$55="Actual")*(Cases_Forecast!$Y$8:$AH$55<>"")) | C32: =0 | D32: =IF(B32=C32,"OK","WARN")
A33: =Inputs!$A$36&": forecast months where CPLH moves more than the tolerance vs LY" | B33: =COUNTIF('NSW-1'!AG15:AG62,">"&CPLHTol)+COUNTIF('NSW-1'!AG15:AG62,"<"&-CPLHTol) | C33: =0 | D33: =IF(B33=C33,"OK","WARN")
A34: =Inputs!$A$37&": forecast months where CPLH moves more than the tolerance vs LY" | B34: =COUNTIF('VIC-1'!AG15:AG62,">"&CPLHTol)+COUNTIF('VIC-1'!AG15:AG62,"<"&-CPLHTol) | C34: =0 | D34: =IF(B34=C34,"OK","WARN")
A35: =Inputs!$A$38&": forecast months where CPLH moves more than the tolerance vs LY" | B35: =COUNTIF('QLD-1'!AG15:AG62,">"&CPLHTol)+COUNTIF('QLD-1'!AG15:AG62,"<"&-CPLHTol) | C35: =0 | D35: =IF(B35=C35,"OK","WARN")
A36: =Inputs!$A$39&": forecast months where CPLH moves more than the tolerance vs LY" | B36: =COUNTIF('NSW-2'!AG15:AG62,">"&CPLHTol)+COUNTIF('NSW-2'!AG15:AG62,"<"&-CPLHTol) | C36: =0 | D36: =IF(B36=C36,"OK","WARN")
A37: =Inputs!$A$40&": forecast months where CPLH moves more than the tolerance vs LY" | B37: =COUNTIF('VIC-2'!AG15:AG62,">"&CPLHTol)+COUNTIF('VIC-2'!AG15:AG62,"<"&-CPLHTol) | C37: =0 | D37: =IF(B37=C37,"OK","WARN")
A38: =Inputs!$A$41&": forecast months where CPLH moves more than the tolerance vs LY" | B38: =COUNTIF('QLD-2'!AG15:AG62,">"&CPLHTol)+COUNTIF('QLD-2'!AG15:AG62,"<"&-CPLHTol) | C38: =0 | D38: =IF(B38=C38,"OK","WARN")
A39: =Inputs!$A$42&": forecast months where CPLH moves more than the tolerance vs LY" | B39: =COUNTIF('SA-1'!AG15:AG62,">"&CPLHTol)+COUNTIF('SA-1'!AG15:AG62,"<"&-CPLHTol) | C39: =0 | D39: =IF(B39=C39,"OK","WARN")
A40: =Inputs!$A$43&": forecast months where CPLH moves more than the tolerance vs LY" | B40: =COUNTIF('WA-1'!AG15:AG62,">"&CPLHTol)+COUNTIF('WA-1'!AG15:AG62,"<"&-CPLHTol) | C40: =0 | D40: =IF(B40=C40,"OK","WARN")
A41: =Inputs!$A$44&": forecast months where CPLH moves more than the tolerance vs LY" | B41: =COUNTIF('IDC-NSW'!AG15:AG62,">"&CPLHTol)+COUNTIF('IDC-NSW'!AG15:AG62,"<"&-CPLHTol) | C41: =0 | D41: =IF(B41=C41,"OK","WARN")
A42: =Inputs!$A$45&": forecast months where CPLH moves more than the tolerance vs LY" | B42: =COUNTIF('IDC-VIC'!AG15:AG62,">"&CPLHTol)+COUNTIF('IDC-VIC'!AG15:AG62,"<"&-CPLHTol) | C42: =0 | D42: =IF(B42=C42,"OK","WARN")

Sheet National
A1: National | 8 regions + 2 IDCs | sales exclude IDCs
A2: Model status | B2: =Checks!B3
R4: Total payroll ($m)
A5: FY | D5: Status | E5: Sales | F5: Cases picked | G5: WH hours worked | H5: Staff payroll | I5: Leadership payroll | J5: Total payroll | K5: CPLH (cases / hr) | L5: Cost per hour (staff) | M5: Cost per case (total payroll) | N5: Total payroll % sales | O5: Leadership % of total payroll | R5: Site | S5: FY2025 | T5: FY2026 | U5: FY2027 | V5: FY2028
A6: 2025 | D6: =IF(DATE(A6,12,1)<=LastActual,"Actual",IF(DATE(A6,1,1)>LastActual,"Forecast","Blended")) | E6: =SUMIFS($E$15:$E$62,$B$15:$B$62,$A6) | F6: =SUMIFS($F$15:$F$62,$B$15:$B$62,$A6) | G6: =SUMIFS($G$15:$G$62,$B$15:$B$62,$A6) | H6: =SUMIFS($H$15:$H$62,$B$15:$B$62,$A6) | I6: =SUMIFS($I$15:$I$62,$B$15:$B$62,$A6) | J6: =SUMIFS($J$15:$J$62,$B$15:$B$62,$A6) | K6: =IFERROR(F6/G6,0) | L6: =IFERROR(H6/G6,0) | M6: =IFERROR(J6/F6,0) | N6: =IFERROR(J6/E6,0) | O6: =IFERROR(I6/J6,0) | R6: =Inputs!$A$36 | S6: =SUMIFS('NSW-1'!$J$15:$J$62,'NSW-1'!$B$15:$B$62,2025) | T6: =SUMIFS('NSW-1'!$J$15:$J$62,'NSW-1'!$B$15:$B$62,2026) | U6: =SUMIFS('NSW-1'!$J$15:$J$62,'NSW-1'!$B$15:$B$62,2027) | V6: =SUMIFS('NSW-1'!$J$15:$J$62,'NSW-1'!$B$15:$B$62,2028)
A7: 2026 | D7: =IF(DATE(A7,12,1)<=LastActual,"Actual",IF(DATE(A7,1,1)>LastActual,"Forecast","Blended")) | E7: =SUMIFS($E$15:$E$62,$B$15:$B$62,$A7) | F7: =SUMIFS($F$15:$F$62,$B$15:$B$62,$A7) | G7: =SUMIFS($G$15:$G$62,$B$15:$B$62,$A7) | H7: =SUMIFS($H$15:$H$62,$B$15:$B$62,$A7) | I7: =SUMIFS($I$15:$I$62,$B$15:$B$62,$A7) | J7: =SUMIFS($J$15:$J$62,$B$15:$B$62,$A7) | K7: =IFERROR(F7/G7,0) | L7: =IFERROR(H7/G7,0) | M7: =IFERROR(J7/F7,0) | N7: =IFERROR(J7/E7,0) | O7: =IFERROR(I7/J7,0) | R7: =Inputs!$A$37 | S7: =SUMIFS('VIC-1'!$J$15:$J$62,'VIC-1'!$B$15:$B$62,2025) | T7: =SUMIFS('VIC-1'!$J$15:$J$62,'VIC-1'!$B$15:$B$62,2026) | U7: =SUMIFS('VIC-1'!$J$15:$J$62,'VIC-1'!$B$15:$B$62,2027) | V7: =SUMIFS('VIC-1'!$J$15:$J$62,'VIC-1'!$B$15:$B$62,2028)
A8: 2027 | D8: =IF(DATE(A8,12,1)<=LastActual,"Actual",IF(DATE(A8,1,1)>LastActual,"Forecast","Blended")) | E8: =SUMIFS($E$15:$E$62,$B$15:$B$62,$A8) | F8: =SUMIFS($F$15:$F$62,$B$15:$B$62,$A8) | G8: =SUMIFS($G$15:$G$62,$B$15:$B$62,$A8) | H8: =SUMIFS($H$15:$H$62,$B$15:$B$62,$A8) | I8: =SUMIFS($I$15:$I$62,$B$15:$B$62,$A8) | J8: =SUMIFS($J$15:$J$62,$B$15:$B$62,$A8) | K8: =IFERROR(F8/G8,0) | L8: =IFERROR(H8/G8,0) | M8: =IFERROR(J8/F8,0) | N8: =IFERROR(J8/E8,0) | O8: =IFERROR(I8/J8,0) | R8: =Inputs!$A$38 | S8: =SUMIFS('QLD-1'!$J$15:$J$62,'QLD-1'!$B$15:$B$62,2025) | T8: =SUMIFS('QLD-1'!$J$15:$J$62,'QLD-1'!$B$15:$B$62,2026) | U8: =SUMIFS('QLD-1'!$J$15:$J$62,'QLD-1'!$B$15:$B$62,2027) | V8: =SUMIFS('QLD-1'!$J$15:$J$62,'QLD-1'!$B$15:$B$62,2028)
A9: 2028 | D9: =IF(DATE(A9,12,1)<=LastActual,"Actual",IF(DATE(A9,1,1)>LastActual,"Forecast","Blended")) | E9: =SUMIFS($E$15:$E$62,$B$15:$B$62,$A9) | F9: =SUMIFS($F$15:$F$62,$B$15:$B$62,$A9) | G9: =SUMIFS($G$15:$G$62,$B$15:$B$62,$A9) | H9: =SUMIFS($H$15:$H$62,$B$15:$B$62,$A9) | I9: =SUMIFS($I$15:$I$62,$B$15:$B$62,$A9) | J9: =SUMIFS($J$15:$J$62,$B$15:$B$62,$A9) | K9: =IFERROR(F9/G9,0) | L9: =IFERROR(H9/G9,0) | M9: =IFERROR(J9/F9,0) | N9: =IFERROR(J9/E9,0) | O9: =IFERROR(I9/J9,0) | R9: =Inputs!$A$39 | S9: =SUMIFS('NSW-2'!$J$15:$J$62,'NSW-2'!$B$15:$B$62,2025) | T9: =SUMIFS('NSW-2'!$J$15:$J$62,'NSW-2'!$B$15:$B$62,2026) | U9: =SUMIFS('NSW-2'!$J$15:$J$62,'NSW-2'!$B$15:$B$62,2027) | V9: =SUMIFS('NSW-2'!$J$15:$J$62,'NSW-2'!$B$15:$B$62,2028)
R10: =Inputs!$A$40 | S10: =SUMIFS('VIC-2'!$J$15:$J$62,'VIC-2'!$B$15:$B$62,2025) | T10: =SUMIFS('VIC-2'!$J$15:$J$62,'VIC-2'!$B$15:$B$62,2026) | U10: =SUMIFS('VIC-2'!$J$15:$J$62,'VIC-2'!$B$15:$B$62,2027) | V10: =SUMIFS('VIC-2'!$J$15:$J$62,'VIC-2'!$B$15:$B$62,2028)
R11: =Inputs!$A$41 | S11: =SUMIFS('QLD-2'!$J$15:$J$62,'QLD-2'!$B$15:$B$62,2025) | T11: =SUMIFS('QLD-2'!$J$15:$J$62,'QLD-2'!$B$15:$B$62,2026) | U11: =SUMIFS('QLD-2'!$J$15:$J$62,'QLD-2'!$B$15:$B$62,2027) | V11: =SUMIFS('QLD-2'!$J$15:$J$62,'QLD-2'!$B$15:$B$62,2028)
E12: Drivers | K12: Metrics | R12: =Inputs!$A$42 | S12: =SUMIFS('SA-1'!$J$15:$J$62,'SA-1'!$B$15:$B$62,2025) | T12: =SUMIFS('SA-1'!$J$15:$J$62,'SA-1'!$B$15:$B$62,2026) | U12: =SUMIFS('SA-1'!$J$15:$J$62,'SA-1'!$B$15:$B$62,2027) | V12: =SUMIFS('SA-1'!$J$15:$J$62,'SA-1'!$B$15:$B$62,2028)
A13: Month | B13: Year | C13: Mth | D13: Status | E13: Sales | F13: Cases picked | G13: WH hours worked | H13: Staff payroll | I13: Leadership payroll | J13: Total payroll | K13: CPLH (cases / hr) | L13: Cost per hour (staff) | M13: Cost per case (total payroll) | N13: Total payroll % sales | O13: Leadership % of total payroll | R13: =Inputs!$A$43 | S13: =SUMIFS('WA-1'!$J$15:$J$62,'WA-1'!$B$15:$B$62,2025) | T13: =SUMIFS('WA-1'!$J$15:$J$62,'WA-1'!$B$15:$B$62,2026) | U13: =SUMIFS('WA-1'!$J$15:$J$62,'WA-1'!$B$15:$B$62,2027) | V13: =SUMIFS('WA-1'!$J$15:$J$62,'WA-1'!$B$15:$B$62,2028)
E14: $m | F14: m | G14: # | H14: $m | I14: $m | J14: $m | K14: # | L14: $ | M14: $ | N14: % | O14: % | R14: =Inputs!$A$44 | S14: =SUMIFS('IDC-NSW'!$J$15:$J$62,'IDC-NSW'!$B$15:$B$62,2025) | T14: =SUMIFS('IDC-NSW'!$J$15:$J$62,'IDC-NSW'!$B$15:$B$62,2026) | U14: =SUMIFS('IDC-NSW'!$J$15:$J$62,'IDC-NSW'!$B$15:$B$62,2027) | V14: =SUMIFS('IDC-NSW'!$J$15:$J$62,'IDC-NSW'!$B$15:$B$62,2028)
A15: 45658 | B15: =YEAR(A15) | C15: =MONTH(A15) | D15: =IF(A15<=LastActual,"Actual","Forecast") | E15: ='NSW-1'!E15+'VIC-1'!E15+'QLD-1'!E15+'NSW-2'!E15+'VIC-2'!E15+'QLD-2'!E15+'SA-1'!E15+'WA-1'!E15 | F15: ='NSW-1'!F15+'VIC-1'!F15+'QLD-1'!F15+'NSW-2'!F15+'VIC-2'!F15+'QLD-2'!F15+'SA-1'!F15+'WA-1'!F15+'IDC-NSW'!F15+'IDC-VIC'!F15 | G15: ='NSW-1'!G15+'VIC-1'!G15+'QLD-1'!G15+'NSW-2'!G15+'VIC-2'!G15+'QLD-2'!G15+'SA-1'!G15+'WA-1'!G15+'IDC-NSW'!G15+'IDC-VIC'!G15 | H15: ='NSW-1'!H15+'VIC-1'!H15+'QLD-1'!H15+'NSW-2'!H15+'VIC-2'!H15+'QLD-2'!H15+'SA-1'!H15+'WA-1'!H15+'IDC-NSW'!H15+'IDC-VIC'!H15 | I15: ='NSW-1'!I15+'VIC-1'!I15+'QLD-1'!I15+'NSW-2'!I15+'VIC-2'!I15+'QLD-2'!I15+'SA-1'!I15+'WA-1'!I15+'IDC-NSW'!I15+'IDC-VIC'!I15 | J15: ='NSW-1'!J15+'VIC-1'!J15+'QLD-1'!J15+'NSW-2'!J15+'VIC-2'!J15+'QLD-2'!J15+'SA-1'!J15+'WA-1'!J15+'IDC-NSW'!J15+'IDC-VIC'!J15 | K15: =IFERROR(F15/G15,0) | L15: =IFERROR(H15/G15,0) | M15: =IFERROR(J15/F15,0) | N15: =IFERROR(J15/E15,0) | O15: =IFERROR(I15/J15,0) | R15: =Inputs!$A$45 | S15: =SUMIFS('IDC-VIC'!$J$15:$J$62,'IDC-VIC'!$B$15:$B$62,2025) | T15: =SUMIFS('IDC-VIC'!$J$15:$J$62,'IDC-VIC'!$B$15:$B$62,2026) | U15: =SUMIFS('IDC-VIC'!$J$15:$J$62,'IDC-VIC'!$B$15:$B$62,2027) | V15: =SUMIFS('IDC-VIC'!$J$15:$J$62,'IDC-VIC'!$B$15:$B$62,2028)
