Workbook
Name LastActual: Inputs!$B$3
Name CPLHTol: Inputs!$B$7
Name CPLHSource: Inputs!$B$9
Name WageDates: Inputs!$A$21:$A$28
Name WageRates: Inputs!$B$21:$B$28
Name PH_Roster: Inputs!$B$31
Name PH_Loading: Inputs!$B$32
Name SiteCodes: Inputs!$A$36:$A$45

Sheet README
A1: Warehouse payroll forecast model (CPLH-driven version, with chambers)
A2: Synthetic data only. Monthly, Jan 2025 to Dec 2028.
A4: THE MODEL (per site, per forecast month)
A5: CPLH and cases are the inputs. Payroll, and payroll % of sales, are the result.
A6: CPLH comes from the CPLH_Forecast tab: plan CPLH (Plan_Inputs, or CPLH_Breakdown if picked on Inputs),
A7: else CPLH in the same month last year; plus your adjustments, or your override.
A8: Cases come from the Cases_Forecast tab: volume driver sales x cases per $ in the same month last year,
A9: plus your adjustments, or your override.
A10: Hours = cases / CPLH.
A11: Cost per hour = same month last year's cost per hour, with last year's public holidays and wage index taken out
A12: and this month's put back in. Staff payroll = hours x cost per hour.
A13: Total payroll = staff payroll / (1 - leadership share of total payroll in the last actual month).
... A44: Public holidays are generated by rule; check against the official state lists (AFL Grand Final Friday in particular).

Sheet Inputs
A1: Inputs
A3: Last actual month | B3: 46266
A5: Model status | B5: =Checks!B3
A7: Warn if forecast CPLH moves more than this vs LY | B7: 0.1
A9: Plan CPLH source | B9: Plan_Inputs | C9: Plan_Inputs = CPLH typed per site per month. National breakdown = the CPLH_Breakdown tab.
A19: Wage increases (staff cost per hour)
A20: Effective month | B20: Increase
A21: 46023 | B21: 0.04 | C21: Include past increases too: last year's cost per hour is divided by its wage index before this year's is applied.
A22: 46388 | B22: 0.045
A23: 46753 | B23: 0.045
A30: Public holidays
A31: Share of normal hours worked on a PH | B31: 0.5
A32: PH pay loading (1.5 = paid 250%) | B32: 1.5
A34: Sites | B34: Type your own codes in the Code column; every tab follows. Renaming the tabs to match is optional.
A35: Code | B35: Type | C35: State | D35: Payroll % basis | E35: In national sales? | F35: Volume driver
A36: NSW-1 | B36: Region | C36: NSW | D36: =A36 | E36: Yes | F36: =A36
A37: VIC-1 | B37: Region | C37: VIC | D37: =A37 | E37: Yes | F37: =A37
A38: QLD-1 | B38: Region | C38: QLD | D38: =A38 | E38: Yes | F38: =A38
A39: NSW-2 | B39: Region | C39: NSW | D39: =A39 | E39: Yes | F39: =A39
A40: VIC-2 | B40: Region | C40: VIC | D40: =A40 | E40: Yes | F40: =A40
A41: QLD-2 | B41: Region | C41: QLD | D41: =A41 | E41: Yes | F41: =A41
A42: SA-1 | B42: Region | C42: SA | D42: =A42 | E42: Yes | F42: =A42
A43: WA-1 | B43: Region | C43: WA | D43: =A43 | E43: Yes | F43: =A43
A44: IDC-NSW | B44: IDC | C44: NSW | D44: =A36 | E44: No | F44: =A36&"+"&A39
A45: IDC-VIC | B45: IDC | C45: VIC | D45: =A37 | E45: No | F45: =A37&"+"&A40

Sheet Data_Actuals
A1: Month | B1: Site | C1: Sales $ | D1: Cases picked | E1: WH hours worked | F1: Staff payroll $ | G1: Leadership payroll $
A2: 45658 | B2: =Inputs!$A$36 | C2: 145185523 | D2: 3043624 | E2: 40295 | F2: 2808121 | G2: 319183
A3: 45658 | B3: =Inputs!$A$37 | C3: 133443243 | D3: 2887489 | E3: 38547 | F3: 2623810 | G3: 302699
A4: 45658 | B4: =Inputs!$A$38 | C4: 111417052 | D4: 2452995 | E4: 34693 | F4: 2319628 | G4: 267794
A5: 45658 | B5: =Inputs!$A$39 | C5: 125154901 | D5: 2690106 | E5: 36126 | F5: 2481070 | G5: 301012
A6: 45658 | B6: =Inputs!$A$40 | C6: 129729431 | D6: 2666780 | E6: 34264 | F6: 2298653 | G6: 303403
A7: 45658 | B7: =Inputs!$A$41 | C7: 117129351 | D7: 2537615 | E7: 35430 | F7: 2331622 | G7: 266309
A8: 45658 | B8: =Inputs!$A$42 | C8: 78517402 | D8: 1794006 | E8: 26280 | F8: 1687827 | G8: 204809
A9: 45658 | B9: =Inputs!$A$43 | C9: 99253181 | D9: 2212340 | E9: 31507 | F9: 2336629 | G9: 248935
A10: 45658 | B10: =Inputs!$A$44 | D10: 814235 | E10: 7750 | F10: 564304 | G10: 149724
A11: 45658 | B11: =Inputs!$A$45 | D11: 745617 | E11: 7313 | F11: 524974 | G11: 142777
A12: 45689 | B12: =Inputs!$A$36 | C12: 132346726 | D12: 2785007 | E12: 36181 | F12: 2383806 | G12: 320742
A13: 45689 | B13: =Inputs!$A$37 | C13: 129246596 | D13: 2777283 | E13: 34519 | F13: 2236585 | G13: 295534
A14: 45689 | B14: =Inputs!$A$38 | C14: 100727414 | D14: 2181145 | E14: 29392 | F14: 1832372 | G14: 257979
A15: 45689 | B15: =Inputs!$A$39 | C15: 110794435 | D15: 2337164 | E15: 31366 | F15: 2097121 | G15: 282353
A16: 45689 | B16: =Inputs!$A$40 | C16: 122688392 | D16: 2600981 | E16: 33068 | F16: 2113994 | G16: 294983
A17: 45689 | B17: =Inputs!$A$41 | C17: 109162992 | D17: 2365350 | E17: 31471 | F17: 1991983 | G17: 275619
A18: 45689 | B18: =Inputs!$A$42 | C18: 70749655 | D18: 1615239 | E18: 22417 | F18: 1358641 | G18: 210920
A19: 45689 | B19: =Inputs!$A$43 | C19: 94123598 | D19: 2117036 | E19: 29338 | F19: 2028412 | G19: 245629
A20: 45689 | B20: =Inputs!$A$44 | D20: 736093 | E20: 6714 | F20: 471815 | G20: 145495
A21: 45689 | B21: =Inputs!$A$45 | D21: 699658 | E21: 6848 | F21: 467508 | G21: 140341
A22: 45717 | B22: =Inputs!$A$36 | C22: 151388181 | D22: 3208052 | E22: 40660 | F22: 2685948 | G22: 315275
A23: 45717 | B23: =Inputs!$A$37 | C23: 139380637 | D23: 3034799 | E23: 37316 | F23: 2494850 | G23: 319982
A24: 45717 | B24: =Inputs!$A$38 | C24: 115886017 | D24: 2560673 | E24: 34662 | F24: 2185396 | G24: 255961
A25: 45717 | B25: =Inputs!$A$39 | C25: 123027509 | D25: 2608583 | E25: 33988 | F25: 2237477 | G25: 273167
A26: 45717 | B26: =Inputs!$A$40 | C26: 135907959 | D26: 2829800 | E26: 35242 | F26: 2310290 | G26: 298020
A27: 45717 | B27: =Inputs!$A$41 | C27: 122320621 | D27: 2680744 | E27: 35277 | F27: 2213243 | G27: 268586
A28: 45717 | B28: =Inputs!$A$42 | C28: 81234768 | D28: 1826489 | E28: 24500 | F28: 1538671 | G28: 197429
A29: 45717 | B29: =Inputs!$A$43 | C29: 108067323 | D29: 2388750 | E29: 32485 | F29: 2317422 | G29: 248477
A30: 45717 | B30: =Inputs!$A$44 | D30: 809173 | E30: 7223 | F30: 505153 | G30: 146059
A31: 45717 | B31: =Inputs!$A$45 | D31: 778599 | E31: 7397 | F31: 527308 | G31: 140256
A32: 45748 | B32: =Inputs!$A$36 | C32: 147502978 | D32: 3093483 | E32: 39190 | F32: 2940258 | G32: 319320
A33: 45748 | B33: =Inputs!$A$37 | C33: 139729332 | D33: 3011417 | E33: 37754 | F33: 2783718 | G33: 313897
A34: 45748 | B34: =Inputs!$A$38 | C34: 117059467 | D34: 2552888 | E34: 34584 | F34: 2465776 | G34: 260553
A35: 45748 | B35: =Inputs!$A$39 | C35: 123461416 | D35: 2596120 | E35: 34407 | F35: 2569797 | G35: 284117
A36: 45748 | B36: =Inputs!$A$40 | C36: 136765517 | D36: 2877751 | E36: 35707 | F36: 2629214 | G36: 306586
A37: 45748 | B37: =Inputs!$A$41 | C37: 116536673 | D37: 2538303 | E37: 34449 | F37: 2474166 | G37: 272848
A38: 45748 | B38: =Inputs!$A$42 | C38: 79536351 | D38: 1769687 | E38: 24842 | F38: 1722163 | G38: 207265
A39: 45748 | B39: =Inputs!$A$43 | C39: 104847628 | D39: 2342946 | E39: 32011 | F39: 2424086 | G39: 250907
A40: 45748 | B40: =Inputs!$A$44 | D40: 816972 | E40: 7455 | F40: 606629 | G40: 153750
...

Sheet Plan_Inputs
A1: Month | B1: Site | C1: Sales forecast $ | D1: Plan CPLH (cases / hr) | F1: From the long-range plan. IDCs have no sales; their payroll % is shown against the host region's sales.
A2: 46023 | B2: =Inputs!$A$36 | C2: 153814000 | D2: 76.3 | F2: Plan CPLH: blank uses CPLH in the same month last year. CPLH_Breakdown's column-for-pasting matches these rows.
A3: 46023 | B3: =Inputs!$A$37 | C3: 142733000 | D3: 80.7
A4: 46023 | B4: =Inputs!$A$38 | C4: 117343000 | D4: 74.1
A5: 46023 | B5: =Inputs!$A$39 | C5: 126585000 | D5: 75.7
A6: 46023 | B6: =Inputs!$A$40 | C6: 135910000 | D6: 79.7
A7: 46023 | B7: =Inputs!$A$41 | C7: 120851000 | D7: 76.9
A8: 46023 | B8: =Inputs!$A$42 | C8: 79038000 | D8: 72.9
A9: 46023 | B9: =Inputs!$A$43 | C9: 106821000 | D9: 71.4
A10: 46023 | B10: =Inputs!$A$44 | D10: 111.4
A11: 46023 | B11: =Inputs!$A$45 | D11: 106
A12: 46054 | B12: =Inputs!$A$36 | C12: 137092000 | D12: 79.9
A13: 46054 | B13: =Inputs!$A$37 | C13: 131606000 | D13: 84.1
A14: 46054 | B14: =Inputs!$A$38 | C14: 109672000 | D14: 75.2
A15: 46054 | B15: =Inputs!$A$39 | C15: 120059000 | D15: 77.5
A16: 46054 | B16: =Inputs!$A$40 | C16: 129364000 | D16: 80.7
A17: 46054 | B17: =Inputs!$A$41 | C17: 114317000 | D17: 76.5
A18: 46054 | B18: =Inputs!$A$42 | C18: 74441000 | D18: 74.3
A19: 46054 | B19: =Inputs!$A$43 | C19: 96657000 | D19: 74.1
A20: 46054 | B20: =Inputs!$A$44 | D20: 111.5
A21: 46054 | B21: =Inputs!$A$45 | D21: 104.7
A22: 46082 | B22: =Inputs!$A$36 | C22: 157503000 | D22: 81.2
A23: 46082 | B23: =Inputs!$A$37 | C23: 146942000 | D23: 82.6
A24: 46082 | B24: =Inputs!$A$38 | C24: 118790000 | D24: 77.9
A25: 46082 | B25: =Inputs!$A$39 | C25: 132170000 | D25: 80.1
A26: 46082 | B26: =Inputs!$A$40 | C26: 140523000 | D26: 81.4
A27: 46082 | B27: =Inputs!$A$41 | C27: 122798000 | D27: 78
A28: 46082 | B28: =Inputs!$A$42 | C28: 81723000 | D28: 73.1
A29: 46082 | B29: =Inputs!$A$43 | C29: 108203000 | D29: 74.4
A30: 46082 | B30: =Inputs!$A$44 | D30: 110
A31: 46082 | B31: =Inputs!$A$45 | D31: 110
A32: 46113 | B32: =Inputs!$A$36 | C32: 153091000 | D32: 79.1
A33: 46113 | B33: =Inputs!$A$37 | C33: 140264000 | D33: 82.7
A34: 46113 | B34: =Inputs!$A$38 | C34: 116902000 | D34: 77.9
A35: 46113 | B35: =Inputs!$A$39 | C35: 132565000 | D35: 79.1
A36: 46113 | B36: =Inputs!$A$40 | C36: 139867000 | D36: 81.8
A37: 46113 | B37: =Inputs!$A$41 | C37: 125887000 | D37: 78
A38: 46113 | B38: =Inputs!$A$42 | C38: 84196000 | D38: 73
A39: 46113 | B39: =Inputs!$A$43 | C39: 111697000 | D39: 75.5
A40: 46113 | B40: =Inputs!$A$44 | D40: 112.7
...

Sheet Cases_Forecast
A1: Cases forecast
A2: 1. Run rate: volume driver sales x cases per $ of sales in the same month last year. Actual months show actuals.
A3: 2. Adjustments: type extra cases (or negative) for a site and month, e.g. a new store or volume moving between sites.
A4: 3. Override: type the cases you want for a site and month. It replaces 1 + 2. Leave blank to use the model.
A5: 4. Cases used = override if there is one, otherwise run rate + adjustment. This feeds Cases picked on each site tab.
C6: 1. Run-rate forecast | N6: 2. Adjustments (+/- cases) | Y6: 3. Override (replaces 1 + 2) | AJ6: 4. Cases forecast used
A7: Month | B7: Status | C7: =Inputs!$A$36 | D7: =Inputs!$A$37 | E7: =Inputs!$A$38 | F7: =Inputs!$A$39 | G7: =Inputs!$A$40 | H7: =Inputs!$A$41 | I7: =Inputs!$A$42 | J7: =Inputs!$A$43 | K7: =Inputs!$A$44 | L7: =Inputs!$A$45 | N7: =Inputs!$A$36 | O7: =Inputs!$A$37 | P7: =Inputs!$A$38 | Q7: =Inputs!$A$39 | R7: =Inputs!$A$40 | S7: =Inputs!$A$41 | T7: =Inputs!$A$42 | U7: =Inputs!$A$43 | V7: =Inputs!$A$44 | W7: =Inputs!$A$45 | Y7: =Inputs!$A$36 | Z7: =Inputs!$A$37 | AA7: =Inputs!$A$38 | AB7: =Inputs!$A$39 | AC7: =Inputs!$A$40 | AD7: =Inputs!$A$41 | AE7: =Inputs!$A$42 | AF7: =Inputs!$A$43 | AG7: =Inputs!$A$44 | AH7: =Inputs!$A$45 | AJ7: =Inputs!$A$36 | AK7: =Inputs!$A$37 | AL7: =Inputs!$A$38 | AM7: =Inputs!$A$39 | AN7: =Inputs!$A$40 | AO7: =Inputs!$A$41 | AP7: =Inputs!$A$42 | AQ7: =Inputs!$A$43 | AR7: =Inputs!$A$44 | AS7: =Inputs!$A$45
A8: 45658 | B8: =IF(A8<=LastActual,"Actual","Forecast") | C8: =IF($B8="Actual",'NSW-1'!S15,IFERROR('NSW-1'!Y15*'NSW-1'!AB15,0)) | D8: =IF($B8="Actual",'VIC-1'!S15,IFERROR('VIC-1'!Y15*'VIC-1'!AB15,0)) | E8: =IF($B8="Actual",'QLD-1'!S15,IFERROR('QLD-1'!Y15*'QLD-1'!AB15,0)) | F8: =IF($B8="Actual",'NSW-2'!S15,IFERROR('NSW-2'!Y15*'NSW-2'!AB15,0)) | G8: =IF($B8="Actual",'VIC-2'!S15,IFERROR('VIC-2'!Y15*'VIC-2'!AB15,0)) | H8: =IF($B8="Actual",'QLD-2'!S15,IFERROR('QLD-2'!Y15*'QLD-2'!AB15,0)) | I8: =IF($B8="Actual",'SA-1'!S15,IFERROR('SA-1'!Y15*'SA-1'!AB15,0)) | J8: =IF($B8="Actual",'WA-1'!S15,IFERROR('WA-1'!Y15*'WA-1'!AB15,0)) | K8: =IF($B8="Actual",'IDC-NSW'!S15,IFERROR('IDC-NSW'!Y15*'IDC-NSW'!AB15,0)) | L8: =IF($B8="Actual",'IDC-VIC'!S15,IFERROR('IDC-VIC'!Y15*'IDC-VIC'!AB15,0)) | AJ8: =IF($B8="Actual",C8,IF(Y8<>"",Y8,C8+N(N8))) | AK8: =IF($B8="Actual",D8,IF(Z8<>"",Z8,D8+N(O8))) | AL8: =IF($B8="Actual",E8,IF(AA8<>"",AA8,E8+N(P8))) | AM8: =IF($B8="Actual",F8,IF(AB8<>"",AB8,F8+N(Q8))) | AN8: =IF($B8="Actual",G8,IF(AC8<>"",AC8,G8+N(R8))) | AO8: =IF($B8="Actual",H8,IF(AD8<>"",AD8,H8+N(S8))) | AP8: =IF($B8="Actual",I8,IF(AE8<>"",AE8,I8+N(T8))) | AQ8: =IF($B8="Actual",J8,IF(AF8<>"",AF8,J8+N(U8))) | ... AS8: =IF($B8="Actual",L8,IF(AH8<>"",AH8,L8+N(W8)))
A9: 45689 | B9: =IF(A9<=LastActual,"Actual","Forecast") | C9: =IF($B9="Actual",'NSW-1'!S16,IFERROR('NSW-1'!Y16*'NSW-1'!AB16,0)) | D9: =IF($B9="Actual",'VIC-1'!S16,IFERROR('VIC-1'!Y16*'VIC-1'!AB16,0)) | E9: =IF($B9="Actual",'QLD-1'!S16,IFERROR('QLD-1'!Y16*'QLD-1'!AB16,0)) | F9: =IF($B9="Actual",'NSW-2'!S16,IFERROR('NSW-2'!Y16*'NSW-2'!AB16,0)) | G9: =IF($B9="Actual",'VIC-2'!S16,IFERROR('VIC-2'!Y16*'VIC-2'!AB16,0)) | H9: =IF($B9="Actual",'QLD-2'!S16,IFERROR('QLD-2'!Y16*'QLD-2'!AB16,0)) | I9: =IF($B9="Actual",'SA-1'!S16,IFERROR('SA-1'!Y16*'SA-1'!AB16,0)) | J9: =IF($B9="Actual",'WA-1'!S16,IFERROR('WA-1'!Y16*'WA-1'!AB16,0)) | K9: =IF($B9="Actual",'IDC-NSW'!S16,IFERROR('IDC-NSW'!Y16*'IDC-NSW'!AB16,0)) | L9: =IF($B9="Actual",'IDC-VIC'!S16,IFERROR('IDC-VIC'!Y16*'IDC-VIC'!AB16,0)) | AJ9: =IF($B9="Actual",C9,IF(Y9<>"",Y9,C9+N(N9))) | AK9: =IF($B9="Actual",D9,IF(Z9<>"",Z9,D9+N(O9))) | AL9: =IF($B9="Actual",E9,IF(AA9<>"",AA9,E9+N(P9))) | AM9: =IF($B9="Actual",F9,IF(AB9<>"",AB9,F9+N(Q9))) | AN9: =IF($B9="Actual",G9,IF(AC9<>"",AC9,G9+N(R9))) | AO9: =IF($B9="Actual",H9,IF(AD9<>"",AD9,H9+N(S9))) | AP9: =IF($B9="Actual",I9,IF(AE9<>"",AE9,I9+N(T9))) | AQ9: =IF($B9="Actual",J9,IF(AF9<>"",AF9,J9+N(U9))) | ... AS9: =IF($B9="Actual",L9,IF(AH9<>"",AH9,L9+N(W9)))
A10: 45717 | B10: =IF(A10<=LastActual,"Actual","Forecast") | C10: =IF($B10="Actual",'NSW-1'!S17,IFERROR('NSW-1'!Y17*'NSW-1'!AB17,0)) | D10: =IF($B10="Actual",'VIC-1'!S17,IFERROR('VIC-1'!Y17*'VIC-1'!AB17,0)) | E10: =IF($B10="Actual",'QLD-1'!S17,IFERROR('QLD-1'!Y17*'QLD-1'!AB17,0)) | F10: =IF($B10="Actual",'NSW-2'!S17,IFERROR('NSW-2'!Y17*'NSW-2'!AB17,0)) | G10: =IF($B10="Actual",'VIC-2'!S17,IFERROR('VIC-2'!Y17*'VIC-2'!AB17,0)) | H10: =IF($B10="Actual",'QLD-2'!S17,IFERROR('QLD-2'!Y17*'QLD-2'!AB17,0)) | I10: =IF($B10="Actual",'SA-1'!S17,IFERROR('SA-1'!Y17*'SA-1'!AB17,0)) | J10: =IF($B10="Actual",'WA-1'!S17,IFERROR('WA-1'!Y17*'WA-1'!AB17,0)) | K10: =IF($B10="Actual",'IDC-NSW'!S17,IFERROR('IDC-NSW'!Y17*'IDC-NSW'!AB17,0)) | L10: =IF($B10="Actual",'IDC-VIC'!S17,IFERROR('IDC-VIC'!Y17*'IDC-VIC'!AB17,0)) | AJ10: =IF($B10="Actual",C10,IF(Y10<>"",Y10,C10+N(N10))) | AK10: =IF($B10="Actual",D10,IF(Z10<>"",Z10,D10+N(O10))) | AL10: =IF($B10="Actual",E10,IF(AA10<>"",AA10,E10+N(P10))) | AM10: =IF($B10="Actual",F10,IF(AB10<>"",AB10,F10+N(Q10))) | AN10: =IF($B10="Actual",G10,IF(AC10<>"",AC10,G10+N(R10))) | AO10: =IF($B10="Actual",H10,IF(AD10<>"",AD10,H10+N(S10))) | AP10: =IF($B10="Actual",I10,IF(AE10<>"",AE10,I10+N(T10))) | AQ10: =IF($B10="Actual",J10,IF(AF10<>"",AF10,J10+N(U10))) | ... AS10: =IF($B10="Actual",L10,IF(AH10<>"",AH10,L10+N(W10)))
A11: 45748 | B11: =IF(A11<=LastActual,"Actual","Forecast") | C11: =IF($B11="Actual",'NSW-1'!S18,IFERROR('NSW-1'!Y18*'NSW-1'!AB18,0)) | D11: =IF($B11="Actual",'VIC-1'!S18,IFERROR('VIC-1'!Y18*'VIC-1'!AB18,0)) | E11: =IF($B11="Actual",'QLD-1'!S18,IFERROR('QLD-1'!Y18*'QLD-1'!AB18,0)) | F11: =IF($B11="Actual",'NSW-2'!S18,IFERROR('NSW-2'!Y18*'NSW-2'!AB18,0)) | G11: =IF($B11="Actual",'VIC-2'!S18,IFERROR('VIC-2'!Y18*'VIC-2'!AB18,0)) | H11: =IF($B11="Actual",'QLD-2'!S18,IFERROR('QLD-2'!Y18*'QLD-2'!AB18,0)) | I11: =IF($B11="Actual",'SA-1'!S18,IFERROR('SA-1'!Y18*'SA-1'!AB18,0)) | J11: =IF($B11="Actual",'WA-1'!S18,IFERROR('WA-1'!Y18*'WA-1'!AB18,0)) | K11: =IF($B11="Actual",'IDC-NSW'!S18,IFERROR('IDC-NSW'!Y18*'IDC-NSW'!AB18,0)) | L11: =IF($B11="Actual",'IDC-VIC'!S18,IFERROR('IDC-VIC'!Y18*'IDC-VIC'!AB18,0)) | AJ11: =IF($B11="Actual",C11,IF(Y11<>"",Y11,C11+N(N11))) | AK11: =IF($B11="Actual",D11,IF(Z11<>"",Z11,D11+N(O11))) | AL11: =IF($B11="Actual",E11,IF(AA11<>"",AA11,E11+N(P11))) | AM11: =IF($B11="Actual",F11,IF(AB11<>"",AB11,F11+N(Q11))) | AN11: =IF($B11="Actual",G11,IF(AC11<>"",AC11,G11+N(R11))) | AO11: =IF($B11="Actual",H11,IF(AD11<>"",AD11,H11+N(S11))) | AP11: =IF($B11="Actual",I11,IF(AE11<>"",AE11,I11+N(T11))) | AQ11: =IF($B11="Actual",J11,IF(AF11<>"",AF11,J11+N(U11))) | ... AS11: =IF($B11="Actual",L11,IF(AH11<>"",AH11,L11+N(W11)))
A12: 45778 | B12: =IF(A12<=LastActual,"Actual","Forecast") | C12: =IF($B12="Actual",'NSW-1'!S19,IFERROR('NSW-1'!Y19*'NSW-1'!AB19,0)) | D12: =IF($B12="Actual",'VIC-1'!S19,IFERROR('VIC-1'!Y19*'VIC-1'!AB19,0)) | E12: =IF($B12="Actual",'QLD-1'!S19,IFERROR('QLD-1'!Y19*'QLD-1'!AB19,0)) | F12: =IF($B12="Actual",'NSW-2'!S19,IFERROR('NSW-2'!Y19*'NSW-2'!AB19,0)) | G12: =IF($B12="Actual",'VIC-2'!S19,IFERROR('VIC-2'!Y19*'VIC-2'!AB19,0)) | H12: =IF($B12="Actual",'QLD-2'!S19,IFERROR('QLD-2'!Y19*'QLD-2'!AB19,0)) | I12: =IF($B12="Actual",'SA-1'!S19,IFERROR('SA-1'!Y19*'SA-1'!AB19,0)) | J12: =IF($B12="Actual",'WA-1'!S19,IFERROR('WA-1'!Y19*'WA-1'!AB19,0)) | K12: =IF($B12="Actual",'IDC-NSW'!S19,IFERROR('IDC-NSW'!Y19*'IDC-NSW'!AB19,0)) | L12: =IF($B12="Actual",'IDC-VIC'!S19,IFERROR('IDC-VIC'!Y19*'IDC-VIC'!AB19,0)) | AJ12: =IF($B12="Actual",C12,IF(Y12<>"",Y12,C12+N(N12))) | AK12: =IF($B12="Actual",D12,IF(Z12<>"",Z12,D12+N(O12))) | AL12: =IF($B12="Actual",E12,IF(AA12<>"",AA12,E12+N(P12))) | AM12: =IF($B12="Actual",F12,IF(AB12<>"",AB12,F12+N(Q12))) | AN12: =IF($B12="Actual",G12,IF(AC12<>"",AC12,G12+N(R12))) | AO12: =IF($B12="Actual",H12,IF(AD12<>"",AD12,H12+N(S12))) | AP12: =IF($B12="Actual",I12,IF(AE12<>"",AE12,I12+N(T12))) | AQ12: =IF($B12="Actual",J12,IF(AF12<>"",AF12,J12+N(U12))) | ... AS12: =IF($B12="Actual",L12,IF(AH12<>"",AH12,L12+N(W12)))
A13: 45809 | B13: =IF(A13<=LastActual,"Actual","Forecast") | C13: =IF($B13="Actual",'NSW-1'!S20,IFERROR('NSW-1'!Y20*'NSW-1'!AB20,0)) | D13: =IF($B13="Actual",'VIC-1'!S20,IFERROR('VIC-1'!Y20*'VIC-1'!AB20,0)) | E13: =IF($B13="Actual",'QLD-1'!S20,IFERROR('QLD-1'!Y20*'QLD-1'!AB20,0)) | F13: =IF($B13="Actual",'NSW-2'!S20,IFERROR('NSW-2'!Y20*'NSW-2'!AB20,0)) | G13: =IF($B13="Actual",'VIC-2'!S20,IFERROR('VIC-2'!Y20*'VIC-2'!AB20,0)) | H13: =IF($B13="Actual",'QLD-2'!S20,IFERROR('QLD-2'!Y20*'QLD-2'!AB20,0)) | I13: =IF($B13="Actual",'SA-1'!S20,IFERROR('SA-1'!Y20*'SA-1'!AB20,0)) | J13: =IF($B13="Actual",'WA-1'!S20,IFERROR('WA-1'!Y20*'WA-1'!AB20,0)) | K13: =IF($B13="Actual",'IDC-NSW'!S20,IFERROR('IDC-NSW'!Y20*'IDC-NSW'!AB20,0)) | L13: =IF($B13="Actual",'IDC-VIC'!S20,IFERROR('IDC-VIC'!Y20*'IDC-VIC'!AB20,0)) | AJ13: =IF($B13="Actual",C13,IF(Y13<>"",Y13,C13+N(N13))) | AK13: =IF($B13="Actual",D13,IF(Z13<>"",Z13,D13+N(O13))) | AL13: =IF($B13="Actual",E13,IF(AA13<>"",AA13,E13+N(P13))) | AM13: =IF($B13="Actual",F13,IF(AB13<>"",AB13,F13+N(Q13))) | AN13: =IF($B13="Actual",G13,IF(AC13<>"",AC13,G13+N(R13))) | AO13: =IF($B13="Actual",H13,IF(AD13<>"",AD13,H13+N(S13))) | AP13: =IF($B13="Actual",I13,IF(AE13<>"",AE13,I13+N(T13))) | AQ13: =IF($B13="Actual",J13,IF(AF13<>"",AF13,J13+N(U13))) | ... AS13: =IF($B13="Actual",L13,IF(AH13<>"",AH13,L13+N(W13)))
A14: 45839 | B14: =IF(A14<=LastActual,"Actual","Forecast") | C14: =IF($B14="Actual",'NSW-1'!S21,IFERROR('NSW-1'!Y21*'NSW-1'!AB21,0)) | D14: =IF($B14="Actual",'VIC-1'!S21,IFERROR('VIC-1'!Y21*'VIC-1'!AB21,0)) | E14: =IF($B14="Actual",'QLD-1'!S21,IFERROR('QLD-1'!Y21*'QLD-1'!AB21,0)) | F14: =IF($B14="Actual",'NSW-2'!S21,IFERROR('NSW-2'!Y21*'NSW-2'!AB21,0)) | G14: =IF($B14="Actual",'VIC-2'!S21,IFERROR('VIC-2'!Y21*'VIC-2'!AB21,0)) | H14: =IF($B14="Actual",'QLD-2'!S21,IFERROR('QLD-2'!Y21*'QLD-2'!AB21,0)) | I14: =IF($B14="Actual",'SA-1'!S21,IFERROR('SA-1'!Y21*'SA-1'!AB21,0)) | J14: =IF($B14="Actual",'WA-1'!S21,IFERROR('WA-1'!Y21*'WA-1'!AB21,0)) | K14: =IF($B14="Actual",'IDC-NSW'!S21,IFERROR('IDC-NSW'!Y21*'IDC-NSW'!AB21,0)) | L14: =IF($B14="Actual",'IDC-VIC'!S21,IFERROR('IDC-VIC'!Y21*'IDC-VIC'!AB21,0)) | AJ14: =IF($B14="Actual",C14,IF(Y14<>"",Y14,C14+N(N14))) | AK14: =IF($B14="Actual",D14,IF(Z14<>"",Z14,D14+N(O14))) | AL14: =IF($B14="Actual",E14,IF(AA14<>"",AA14,E14+N(P14))) | AM14: =IF($B14="Actual",F14,IF(AB14<>"",AB14,F14+N(Q14))) | AN14: =IF($B14="Actual",G14,IF(AC14<>"",AC14,G14+N(R14))) | AO14: =IF($B14="Actual",H14,IF(AD14<>"",AD14,H14+N(S14))) | AP14: =IF($B14="Actual",I14,IF(AE14<>"",AE14,I14+N(T14))) | AQ14: =IF($B14="Actual",J14,IF(AF14<>"",AF14,J14+N(U14))) | ... AS14: =IF($B14="Actual",L14,IF(AH14<>"",AH14,L14+N(W14)))
A15: 45870 | B15: =IF(A15<=LastActual,"Actual","Forecast") | C15: =IF($B15="Actual",'NSW-1'!S22,IFERROR('NSW-1'!Y22*'NSW-1'!AB22,0)) | D15: =IF($B15="Actual",'VIC-1'!S22,IFERROR('VIC-1'!Y22*'VIC-1'!AB22,0)) | E15: =IF($B15="Actual",'QLD-1'!S22,IFERROR('QLD-1'!Y22*'QLD-1'!AB22,0)) | F15: =IF($B15="Actual",'NSW-2'!S22,IFERROR('NSW-2'!Y22*'NSW-2'!AB22,0)) | G15: =IF($B15="Actual",'VIC-2'!S22,IFERROR('VIC-2'!Y22*'VIC-2'!AB22,0)) | H15: =IF($B15="Actual",'QLD-2'!S22,IFERROR('QLD-2'!Y22*'QLD-2'!AB22,0)) | I15: =IF($B15="Actual",'SA-1'!S22,IFERROR('SA-1'!Y22*'SA-1'!AB22,0)) | J15: =IF($B15="Actual",'WA-1'!S22,IFERROR('WA-1'!Y22*'WA-1'!AB22,0)) | K15: =IF($B15="Actual",'IDC-NSW'!S22,IFERROR('IDC-NSW'!Y22*'IDC-NSW'!AB22,0)) | L15: =IF($B15="Actual",'IDC-VIC'!S22,IFERROR('IDC-VIC'!Y22*'IDC-VIC'!AB22,0)) | AJ15: =IF($B15="Actual",C15,IF(Y15<>"",Y15,C15+N(N15))) | AK15: =IF($B15="Actual",D15,IF(Z15<>"",Z15,D15+N(O15))) | AL15: =IF($B15="Actual",E15,IF(AA15<>"",AA15,E15+N(P15))) | AM15: =IF($B15="Actual",F15,IF(AB15<>"",AB15,F15+N(Q15))) | AN15: =IF($B15="Actual",G15,IF(AC15<>"",AC15,G15+N(R15))) | AO15: =IF($B15="Actual",H15,IF(AD15<>"",AD15,H15+N(S15))) | AP15: =IF($B15="Actual",I15,IF(AE15<>"",AE15,I15+N(T15))) | AQ15: =IF($B15="Actual",J15,IF(AF15<>"",AF15,J15+N(U15))) | ... AS15: =IF($B15="Actual",L15,IF(AH15<>"",AH15,L15+N(W15)))
A16: 45901 | B16: =IF(A16<=LastActual,"Actual","Forecast") | C16: =IF($B16="Actual",'NSW-1'!S23,IFERROR('NSW-1'!Y23*'NSW-1'!AB23,0)) | D16: =IF($B16="Actual",'VIC-1'!S23,IFERROR('VIC-1'!Y23*'VIC-1'!AB23,0)) | E16: =IF($B16="Actual",'QLD-1'!S23,IFERROR('QLD-1'!Y23*'QLD-1'!AB23,0)) | F16: =IF($B16="Actual",'NSW-2'!S23,IFERROR('NSW-2'!Y23*'NSW-2'!AB23,0)) | G16: =IF($B16="Actual",'VIC-2'!S23,IFERROR('VIC-2'!Y23*'VIC-2'!AB23,0)) | H16: =IF($B16="Actual",'QLD-2'!S23,IFERROR('QLD-2'!Y23*'QLD-2'!AB23,0)) | I16: =IF($B16="Actual",'SA-1'!S23,IFERROR('SA-1'!Y23*'SA-1'!AB23,0)) | J16: =IF($B16="Actual",'WA-1'!S23,IFERROR('WA-1'!Y23*'WA-1'!AB23,0)) | K16: =IF($B16="Actual",'IDC-NSW'!S23,IFERROR('IDC-NSW'!Y23*'IDC-NSW'!AB23,0)) | L16: =IF($B16="Actual",'IDC-VIC'!S23,IFERROR('IDC-VIC'!Y23*'IDC-VIC'!AB23,0)) | AJ16: =IF($B16="Actual",C16,IF(Y16<>"",Y16,C16+N(N16))) | AK16: =IF($B16="Actual",D16,IF(Z16<>"",Z16,D16+N(O16))) | AL16: =IF($B16="Actual",E16,IF(AA16<>"",AA16,E16+N(P16))) | AM16: =IF($B16="Actual",F16,IF(AB16<>"",AB16,F16+N(Q16))) | AN16: =IF($B16="Actual",G16,IF(AC16<>"",AC16,G16+N(R16))) | AO16: =IF($B16="Actual",H16,IF(AD16<>"",AD16,H16+N(S16))) | AP16: =IF($B16="Actual",I16,IF(AE16<>"",AE16,I16+N(T16))) | AQ16: =IF($B16="Actual",J16,IF(AF16<>"",AF16,J16+N(U16))) | ... AS16: =IF($B16="Actual",L16,IF(AH16<>"",AH16,L16+N(W16)))
A17: 45931 | B17: =IF(A17<=LastActual,"Actual","Forecast") | C17: =IF($B17="Actual",'NSW-1'!S24,IFERROR('NSW-1'!Y24*'NSW-1'!AB24,0)) | D17: =IF($B17="Actual",'VIC-1'!S24,IFERROR('VIC-1'!Y24*'VIC-1'!AB24,0)) | E17: =IF($B17="Actual",'QLD-1'!S24,IFERROR('QLD-1'!Y24*'QLD-1'!AB24,0)) | F17: =IF($B17="Actual",'NSW-2'!S24,IFERROR('NSW-2'!Y24*'NSW-2'!AB24,0)) | G17: =IF($B17="Actual",'VIC-2'!S24,IFERROR('VIC-2'!Y24*'VIC-2'!AB24,0)) | H17: =IF($B17="Actual",'QLD-2'!S24,IFERROR('QLD-2'!Y24*'QLD-2'!AB24,0)) | I17: =IF($B17="Actual",'SA-1'!S24,IFERROR('SA-1'!Y24*'SA-1'!AB24,0)) | J17: =IF($B17="Actual",'WA-1'!S24,IFERROR('WA-1'!Y24*'WA-1'!AB24,0)) | K17: =IF($B17="Actual",'IDC-NSW'!S24,IFERROR('IDC-NSW'!Y24*'IDC-NSW'!AB24,0)) | L17: =IF($B17="Actual",'IDC-VIC'!S24,IFERROR('IDC-VIC'!Y24*'IDC-VIC'!AB24,0)) | AJ17: =IF($B17="Actual",C17,IF(Y17<>"",Y17,C17+N(N17))) | AK17: =IF($B17="Actual",D17,IF(Z17<>"",Z17,D17+N(O17))) | AL17: =IF($B17="Actual",E17,IF(AA17<>"",AA17,E17+N(P17))) | AM17: =IF($B17="Actual",F17,IF(AB17<>"",AB17,F17+N(Q17))) | AN17: =IF($B17="Actual",G17,IF(AC17<>"",AC17,G17+N(R17))) | AO17: =IF($B17="Actual",H17,IF(AD17<>"",AD17,H17+N(S17))) | AP17: =IF($B17="Actual",I17,IF(AE17<>"",AE17,I17+N(T17))) | AQ17: =IF($B17="Actual",J17,IF(AF17<>"",AF17,J17+N(U17))) | ... AS17: =IF($B17="Actual",L17,IF(AH17<>"",AH17,L17+N(W17)))
A18: 45962 | B18: =IF(A18<=LastActual,"Actual","Forecast") | C18: =IF($B18="Actual",'NSW-1'!S25,IFERROR('NSW-1'!Y25*'NSW-1'!AB25,0)) | D18: =IF($B18="Actual",'VIC-1'!S25,IFERROR('VIC-1'!Y25*'VIC-1'!AB25,0)) | E18: =IF($B18="Actual",'QLD-1'!S25,IFERROR('QLD-1'!Y25*'QLD-1'!AB25,0)) | F18: =IF($B18="Actual",'NSW-2'!S25,IFERROR('NSW-2'!Y25*'NSW-2'!AB25,0)) | G18: =IF($B18="Actual",'VIC-2'!S25,IFERROR('VIC-2'!Y25*'VIC-2'!AB25,0)) | H18: =IF($B18="Actual",'QLD-2'!S25,IFERROR('QLD-2'!Y25*'QLD-2'!AB25,0)) | I18: =IF($B18="Actual",'SA-1'!S25,IFERROR('SA-1'!Y25*'SA-1'!AB25,0)) | J18: =IF($B18="Actual",'WA-1'!S25,IFERROR('WA-1'!Y25*'WA-1'!AB25,0)) | K18: =IF($B18="Actual",'IDC-NSW'!S25,IFERROR('IDC-NSW'!Y25*'IDC-NSW'!AB25,0)) | L18: =IF($B18="Actual",'IDC-VIC'!S25,IFERROR('IDC-VIC'!Y25*'IDC-VIC'!AB25,0)) | AJ18: =IF($B18="Actual",C18,IF(Y18<>"",Y18,C18+N(N18))) | AK18: =IF($B18="Actual",D18,IF(Z18<>"",Z18,D18+N(O18))) | AL18: =IF($B18="Actual",E18,IF(AA18<>"",AA18,E18+N(P18))) | AM18: =IF($B18="Actual",F18,IF(AB18<>"",AB18,F18+N(Q18))) | AN18: =IF($B18="Actual",G18,IF(AC18<>"",AC18,G18+N(R18))) | AO18: =IF($B18="Actual",H18,IF(AD18<>"",AD18,H18+N(S18))) | AP18: =IF($B18="Actual",I18,IF(AE18<>"",AE18,I18+N(T18))) | AQ18: =IF($B18="Actual",J18,IF(AF18<>"",AF18,J18+N(U18))) | ... AS18: =IF($B18="Actual",L18,IF(AH18<>"",AH18,L18+N(W18)))
A19: 45992 | B19: =IF(A19<=LastActual,"Actual","Forecast") | C19: =IF($B19="Actual",'NSW-1'!S26,IFERROR('NSW-1'!Y26*'NSW-1'!AB26,0)) | D19: =IF($B19="Actual",'VIC-1'!S26,IFERROR('VIC-1'!Y26*'VIC-1'!AB26,0)) | E19: =IF($B19="Actual",'QLD-1'!S26,IFERROR('QLD-1'!Y26*'QLD-1'!AB26,0)) | F19: =IF($B19="Actual",'NSW-2'!S26,IFERROR('NSW-2'!Y26*'NSW-2'!AB26,0)) | G19: =IF($B19="Actual",'VIC-2'!S26,IFERROR('VIC-2'!Y26*'VIC-2'!AB26,0)) | H19: =IF($B19="Actual",'QLD-2'!S26,IFERROR('QLD-2'!Y26*'QLD-2'!AB26,0)) | I19: =IF($B19="Actual",'SA-1'!S26,IFERROR('SA-1'!Y26*'SA-1'!AB26,0)) | J19: =IF($B19="Actual",'WA-1'!S26,IFERROR('WA-1'!Y26*'WA-1'!AB26,0)) | K19: =IF($B19="Actual",'IDC-NSW'!S26,IFERROR('IDC-NSW'!Y26*'IDC-NSW'!AB26,0)) | L19: =IF($B19="Actual",'IDC-VIC'!S26,IFERROR('IDC-VIC'!Y26*'IDC-VIC'!AB26,0)) | AJ19: =IF($B19="Actual",C19,IF(Y19<>"",Y19,C19+N(N19))) | AK19: =IF($B19="Actual",D19,IF(Z19<>"",Z19,D19+N(O19))) | AL19: =IF($B19="Actual",E19,IF(AA19<>"",AA19,E19+N(P19))) | AM19: =IF($B19="Actual",F19,IF(AB19<>"",AB19,F19+N(Q19))) | AN19: =IF($B19="Actual",G19,IF(AC19<>"",AC19,G19+N(R19))) | AO19: =IF($B19="Actual",H19,IF(AD19<>"",AD19,H19+N(S19))) | AP19: =IF($B19="Actual",I19,IF(AE19<>"",AE19,I19+N(T19))) | AQ19: =IF($B19="Actual",J19,IF(AF19<>"",AF19,J19+N(U19))) | ... AS19: =IF($B19="Actual",L19,IF(AH19<>"",AH19,L19+N(W19)))
... A55: 47088 | B55: =IF(A55<=LastActual,"Actual","Forecast") | C55: =IF($B55="Actual",'NSW-1'!S62,IFERROR('NSW-1'!Y62*'NSW-1'!AB62,0)) | D55: =IF($B55="Actual",'VIC-1'!S62,IFERROR('VIC-1'!Y62*'VIC-1'!AB62,0)) | E55: =IF($B55="Actual",'QLD-1'!S62,IFERROR('QLD-1'!Y62*'QLD-1'!AB62,0)) | F55: =IF($B55="Actual",'NSW-2'!S62,IFERROR('NSW-2'!Y62*'NSW-2'!AB62,0)) | G55: =IF($B55="Actual",'VIC-2'!S62,IFERROR('VIC-2'!Y62*'VIC-2'!AB62,0)) | H55: =IF($B55="Actual",'QLD-2'!S62,IFERROR('QLD-2'!Y62*'QLD-2'!AB62,0)) | I55: =IF($B55="Actual",'SA-1'!S62,IFERROR('SA-1'!Y62*'SA-1'!AB62,0)) | J55: =IF($B55="Actual",'WA-1'!S62,IFERROR('WA-1'!Y62*'WA-1'!AB62,0)) | K55: =IF($B55="Actual",'IDC-NSW'!S62,IFERROR('IDC-NSW'!Y62*'IDC-NSW'!AB62,0)) | L55: =IF($B55="Actual",'IDC-VIC'!S62,IFERROR('IDC-VIC'!Y62*'IDC-VIC'!AB62,0)) | AJ55: =IF($B55="Actual",C55,IF(Y55<>"",Y55,C55+N(N55))) | AK55: =IF($B55="Actual",D55,IF(Z55<>"",Z55,D55+N(O55))) | AL55: =IF($B55="Actual",E55,IF(AA55<>"",AA55,E55+N(P55))) | AM55: =IF($B55="Actual",F55,IF(AB55<>"",AB55,F55+N(Q55))) | AN55: =IF($B55="Actual",G55,IF(AC55<>"",AC55,G55+N(R55))) | AO55: =IF($B55="Actual",H55,IF(AD55<>"",AD55,H55+N(S55))) | AP55: =IF($B55="Actual",I55,IF(AE55<>"",AE55,I55+N(T55))) | AQ55: =IF($B55="Actual",J55,IF(AF55<>"",AF55,J55+N(U55))) | ... AS55: =IF($B55="Actual",L55,IF(AH55<>"",AH55,L55+N(W55)))

Sheet CPLH_Forecast
A1: CPLH forecast (cases per labour hour)
A2: 1. Plan: plan CPLH (Plan_Inputs, or CPLH_Breakdown if picked on Inputs). Blank plan = same month last year. Actuals show actuals.
A3: 2. Adjustments: type a change in cases per hour for a site and month, e.g. +2 for a new pick system.
A4: 3. Override: type the CPLH you want for a site and month, e.g. a target. It replaces 1 + 2. Leave blank to use the model.
A5: 4. CPLH used = override if there is one, otherwise run rate + adjustment. This drives hours, and so payroll, on each site tab.
C6: 1. Plan CPLH (else same month LY) | N6: 2. Adjustments (+/- cases / hr) | Y6: 3. Override (replaces 1 + 2) | AJ6: 4. CPLH forecast used
A7: Month | B7: Status | C7: =Inputs!$A$36 | D7: =Inputs!$A$37 | E7: =Inputs!$A$38 | F7: =Inputs!$A$39 | G7: =Inputs!$A$40 | H7: =Inputs!$A$41 | I7: =Inputs!$A$42 | J7: =Inputs!$A$43 | K7: =Inputs!$A$44 | L7: =Inputs!$A$45 | N7: =Inputs!$A$36 | O7: =Inputs!$A$37 | P7: =Inputs!$A$38 | Q7: =Inputs!$A$39 | R7: =Inputs!$A$40 | S7: =Inputs!$A$41 | T7: =Inputs!$A$42 | U7: =Inputs!$A$43 | V7: =Inputs!$A$44 | W7: =Inputs!$A$45 | Y7: =Inputs!$A$36 | Z7: =Inputs!$A$37 | AA7: =Inputs!$A$38 | AB7: =Inputs!$A$39 | AC7: =Inputs!$A$40 | AD7: =Inputs!$A$41 | AE7: =Inputs!$A$42 | AF7: =Inputs!$A$43 | AG7: =Inputs!$A$44 | AH7: =Inputs!$A$45 | AJ7: =Inputs!$A$36 | AK7: =Inputs!$A$37 | AL7: =Inputs!$A$38 | AM7: =Inputs!$A$39 | AN7: =Inputs!$A$40 | AO7: =Inputs!$A$41 | AP7: =Inputs!$A$42 | AQ7: =Inputs!$A$43 | AR7: =Inputs!$A$44 | AS7: =Inputs!$A$45
A8: 45658 | B8: =IF(A8<=LastActual,"Actual","Forecast") | C8: =IF(AND($B8="Forecast",N('NSW-1'!AH15)>0),'NSW-1'!AH15,IFERROR('NSW-1'!X15*1,0)) | D8: =IF(AND($B8="Forecast",N('VIC-1'!AH15)>0),'VIC-1'!AH15,IFERROR('VIC-1'!X15*1,0)) | E8: =IF(AND($B8="Forecast",N('QLD-1'!AH15)>0),'QLD-1'!AH15,IFERROR('QLD-1'!X15*1,0)) | F8: =IF(AND($B8="Forecast",N('NSW-2'!AH15)>0),'NSW-2'!AH15,IFERROR('NSW-2'!X15*1,0)) | G8: =IF(AND($B8="Forecast",N('VIC-2'!AH15)>0),'VIC-2'!AH15,IFERROR('VIC-2'!X15*1,0)) | H8: =IF(AND($B8="Forecast",N('QLD-2'!AH15)>0),'QLD-2'!AH15,IFERROR('QLD-2'!X15*1,0)) | I8: =IF(AND($B8="Forecast",N('SA-1'!AH15)>0),'SA-1'!AH15,IFERROR('SA-1'!X15*1,0)) | J8: =IF(AND($B8="Forecast",N('WA-1'!AH15)>0),'WA-1'!AH15,IFERROR('WA-1'!X15*1,0)) | K8: =IF(AND($B8="Forecast",N('IDC-NSW'!AH15)>0),'IDC-NSW'!AH15,IFERROR('IDC-NSW'!X15*1,0)) | L8: =IF(AND($B8="Forecast",N('IDC-VIC'!AH15)>0),'IDC-VIC'!AH15,IFERROR('IDC-VIC'!X15*1,0)) | AJ8: =IF($B8="Actual",C8,IF(Y8<>"",Y8,C8+N(N8))) | AK8: =IF($B8="Actual",D8,IF(Z8<>"",Z8,D8+N(O8))) | AL8: =IF($B8="Actual",E8,IF(AA8<>"",AA8,E8+N(P8))) | AM8: =IF($B8="Actual",F8,IF(AB8<>"",AB8,F8+N(Q8))) | AN8: =IF($B8="Actual",G8,IF(AC8<>"",AC8,G8+N(R8))) | AO8: =IF($B8="Actual",H8,IF(AD8<>"",AD8,H8+N(S8))) | AP8: =IF($B8="Actual",I8,IF(AE8<>"",AE8,I8+N(T8))) | AQ8: =IF($B8="Actual",J8,IF(AF8<>"",AF8,J8+N(U8))) | ... AS8: =IF($B8="Actual",L8,IF(AH8<>"",AH8,L8+N(W8)))
A9: 45689 | B9: =IF(A9<=LastActual,"Actual","Forecast") | C9: =IF(AND($B9="Forecast",N('NSW-1'!AH16)>0),'NSW-1'!AH16,IFERROR('NSW-1'!X16*1,0)) | D9: =IF(AND($B9="Forecast",N('VIC-1'!AH16)>0),'VIC-1'!AH16,IFERROR('VIC-1'!X16*1,0)) | E9: =IF(AND($B9="Forecast",N('QLD-1'!AH16)>0),'QLD-1'!AH16,IFERROR('QLD-1'!X16*1,0)) | F9: =IF(AND($B9="Forecast",N('NSW-2'!AH16)>0),'NSW-2'!AH16,IFERROR('NSW-2'!X16*1,0)) | G9: =IF(AND($B9="Forecast",N('VIC-2'!AH16)>0),'VIC-2'!AH16,IFERROR('VIC-2'!X16*1,0)) | H9: =IF(AND($B9="Forecast",N('QLD-2'!AH16)>0),'QLD-2'!AH16,IFERROR('QLD-2'!X16*1,0)) | I9: =IF(AND($B9="Forecast",N('SA-1'!AH16)>0),'SA-1'!AH16,IFERROR('SA-1'!X16*1,0)) | J9: =IF(AND($B9="Forecast",N('WA-1'!AH16)>0),'WA-1'!AH16,IFERROR('WA-1'!X16*1,0)) | K9: =IF(AND($B9="Forecast",N('IDC-NSW'!AH16)>0),'IDC-NSW'!AH16,IFERROR('IDC-NSW'!X16*1,0)) | L9: =IF(AND($B9="Forecast",N('IDC-VIC'!AH16)>0),'IDC-VIC'!AH16,IFERROR('IDC-VIC'!X16*1,0)) | AJ9: =IF($B9="Actual",C9,IF(Y9<>"",Y9,C9+N(N9))) | AK9: =IF($B9="Actual",D9,IF(Z9<>"",Z9,D9+N(O9))) | AL9: =IF($B9="Actual",E9,IF(AA9<>"",AA9,E9+N(P9))) | AM9: =IF($B9="Actual",F9,IF(AB9<>"",AB9,F9+N(Q9))) | AN9: =IF($B9="Actual",G9,IF(AC9<>"",AC9,G9+N(R9))) | AO9: =IF($B9="Actual",H9,IF(AD9<>"",AD9,H9+N(S9))) | AP9: =IF($B9="Actual",I9,IF(AE9<>"",AE9,I9+N(T9))) | AQ9: =IF($B9="Actual",J9,IF(AF9<>"",AF9,J9+N(U9))) | ... AS9: =IF($B9="Actual",L9,IF(AH9<>"",AH9,L9+N(W9)))
A10: 45717 | B10: =IF(A10<=LastActual,"Actual","Forecast") | C10: =IF(AND($B10="Forecast",N('NSW-1'!AH17)>0),'NSW-1'!AH17,IFERROR('NSW-1'!X17*1,0)) | D10: =IF(AND($B10="Forecast",N('VIC-1'!AH17)>0),'VIC-1'!AH17,IFERROR('VIC-1'!X17*1,0)) | E10: =IF(AND($B10="Forecast",N('QLD-1'!AH17)>0),'QLD-1'!AH17,IFERROR('QLD-1'!X17*1,0)) | F10: =IF(AND($B10="Forecast",N('NSW-2'!AH17)>0),'NSW-2'!AH17,IFERROR('NSW-2'!X17*1,0)) | G10: =IF(AND($B10="Forecast",N('VIC-2'!AH17)>0),'VIC-2'!AH17,IFERROR('VIC-2'!X17*1,0)) | H10: =IF(AND($B10="Forecast",N('QLD-2'!AH17)>0),'QLD-2'!AH17,IFERROR('QLD-2'!X17*1,0)) | I10: =IF(AND($B10="Forecast",N('SA-1'!AH17)>0),'SA-1'!AH17,IFERROR('SA-1'!X17*1,0)) | J10: =IF(AND($B10="Forecast",N('WA-1'!AH17)>0),'WA-1'!AH17,IFERROR('WA-1'!X17*1,0)) | K10: =IF(AND($B10="Forecast",N('IDC-NSW'!AH17)>0),'IDC-NSW'!AH17,IFERROR('IDC-NSW'!X17*1,0)) | L10: =IF(AND($B10="Forecast",N('IDC-VIC'!AH17)>0),'IDC-VIC'!AH17,IFERROR('IDC-VIC'!X17*1,0)) | AJ10: =IF($B10="Actual",C10,IF(Y10<>"",Y10,C10+N(N10))) | AK10: =IF($B10="Actual",D10,IF(Z10<>"",Z10,D10+N(O10))) | AL10: =IF($B10="Actual",E10,IF(AA10<>"",AA10,E10+N(P10))) | AM10: =IF($B10="Actual",F10,IF(AB10<>"",AB10,F10+N(Q10))) | AN10: =IF($B10="Actual",G10,IF(AC10<>"",AC10,G10+N(R10))) | AO10: =IF($B10="Actual",H10,IF(AD10<>"",AD10,H10+N(S10))) | AP10: =IF($B10="Actual",I10,IF(AE10<>"",AE10,I10+N(T10))) | AQ10: =IF($B10="Actual",J10,IF(AF10<>"",AF10,J10+N(U10))) | ... AS10: =IF($B10="Actual",L10,IF(AH10<>"",AH10,L10+N(W10)))
A11: 45748 | B11: =IF(A11<=LastActual,"Actual","Forecast") | C11: =IF(AND($B11="Forecast",N('NSW-1'!AH18)>0),'NSW-1'!AH18,IFERROR('NSW-1'!X18*1,0)) | D11: =IF(AND($B11="Forecast",N('VIC-1'!AH18)>0),'VIC-1'!AH18,IFERROR('VIC-1'!X18*1,0)) | E11: =IF(AND($B11="Forecast",N('QLD-1'!AH18)>0),'QLD-1'!AH18,IFERROR('QLD-1'!X18*1,0)) | F11: =IF(AND($B11="Forecast",N('NSW-2'!AH18)>0),'NSW-2'!AH18,IFERROR('NSW-2'!X18*1,0)) | G11: =IF(AND($B11="Forecast",N('VIC-2'!AH18)>0),'VIC-2'!AH18,IFERROR('VIC-2'!X18*1,0)) | H11: =IF(AND($B11="Forecast",N('QLD-2'!AH18)>0),'QLD-2'!AH18,IFERROR('QLD-2'!X18*1,0)) | I11: =IF(AND($B11="Forecast",N('SA-1'!AH18)>0),'SA-1'!AH18,IFERROR('SA-1'!X18*1,0)) | J11: =IF(AND($B11="Forecast",N('WA-1'!AH18)>0),'WA-1'!AH18,IFERROR('WA-1'!X18*1,0)) | K11: =IF(AND($B11="Forecast",N('IDC-NSW'!AH18)>0),'IDC-NSW'!AH18,IFERROR('IDC-NSW'!X18*1,0)) | L11: =IF(AND($B11="Forecast",N('IDC-VIC'!AH18)>0),'IDC-VIC'!AH18,IFERROR('IDC-VIC'!X18*1,0)) | AJ11: =IF($B11="Actual",C11,IF(Y11<>"",Y11,C11+N(N11))) | AK11: =IF($B11="Actual",D11,IF(Z11<>"",Z11,D11+N(O11))) | AL11: =IF($B11="Actual",E11,IF(AA11<>"",AA11,E11+N(P11))) | AM11: =IF($B11="Actual",F11,IF(AB11<>"",AB11,F11+N(Q11))) | AN11: =IF($B11="Actual",G11,IF(AC11<>"",AC11,G11+N(R11))) | AO11: =IF($B11="Actual",H11,IF(AD11<>"",AD11,H11+N(S11))) | AP11: =IF($B11="Actual",I11,IF(AE11<>"",AE11,I11+N(T11))) | AQ11: =IF($B11="Actual",J11,IF(AF11<>"",AF11,J11+N(U11))) | ... AS11: =IF($B11="Actual",L11,IF(AH11<>"",AH11,L11+N(W11)))
A12: 45778 | B12: =IF(A12<=LastActual,"Actual","Forecast") | C12: =IF(AND($B12="Forecast",N('NSW-1'!AH19)>0),'NSW-1'!AH19,IFERROR('NSW-1'!X19*1,0)) | D12: =IF(AND($B12="Forecast",N('VIC-1'!AH19)>0),'VIC-1'!AH19,IFERROR('VIC-1'!X19*1,0)) | E12: =IF(AND($B12="Forecast",N('QLD-1'!AH19)>0),'QLD-1'!AH19,IFERROR('QLD-1'!X19*1,0)) | F12: =IF(AND($B12="Forecast",N('NSW-2'!AH19)>0),'NSW-2'!AH19,IFERROR('NSW-2'!X19*1,0)) | G12: =IF(AND($B12="Forecast",N('VIC-2'!AH19)>0),'VIC-2'!AH19,IFERROR('VIC-2'!X19*1,0)) | H12: =IF(AND($B12="Forecast",N('QLD-2'!AH19)>0),'QLD-2'!AH19,IFERROR('QLD-2'!X19*1,0)) | I12: =IF(AND($B12="Forecast",N('SA-1'!AH19)>0),'SA-1'!AH19,IFERROR('SA-1'!X19*1,0)) | J12: =IF(AND($B12="Forecast",N('WA-1'!AH19)>0),'WA-1'!AH19,IFERROR('WA-1'!X19*1,0)) | K12: =IF(AND($B12="Forecast",N('IDC-NSW'!AH19)>0),'IDC-NSW'!AH19,IFERROR('IDC-NSW'!X19*1,0)) | L12: =IF(AND($B12="Forecast",N('IDC-VIC'!AH19)>0),'IDC-VIC'!AH19,IFERROR('IDC-VIC'!X19*1,0)) | AJ12: =IF($B12="Actual",C12,IF(Y12<>"",Y12,C12+N(N12))) | AK12: =IF($B12="Actual",D12,IF(Z12<>"",Z12,D12+N(O12))) | AL12: =IF($B12="Actual",E12,IF(AA12<>"",AA12,E12+N(P12))) | AM12: =IF($B12="Actual",F12,IF(AB12<>"",AB12,F12+N(Q12))) | AN12: =IF($B12="Actual",G12,IF(AC12<>"",AC12,G12+N(R12))) | AO12: =IF($B12="Actual",H12,IF(AD12<>"",AD12,H12+N(S12))) | AP12: =IF($B12="Actual",I12,IF(AE12<>"",AE12,I12+N(T12))) | AQ12: =IF($B12="Actual",J12,IF(AF12<>"",AF12,J12+N(U12))) | ... AS12: =IF($B12="Actual",L12,IF(AH12<>"",AH12,L12+N(W12)))
A13: 45809 | B13: =IF(A13<=LastActual,"Actual","Forecast") | C13: =IF(AND($B13="Forecast",N('NSW-1'!AH20)>0),'NSW-1'!AH20,IFERROR('NSW-1'!X20*1,0)) | D13: =IF(AND($B13="Forecast",N('VIC-1'!AH20)>0),'VIC-1'!AH20,IFERROR('VIC-1'!X20*1,0)) | E13: =IF(AND($B13="Forecast",N('QLD-1'!AH20)>0),'QLD-1'!AH20,IFERROR('QLD-1'!X20*1,0)) | F13: =IF(AND($B13="Forecast",N('NSW-2'!AH20)>0),'NSW-2'!AH20,IFERROR('NSW-2'!X20*1,0)) | G13: =IF(AND($B13="Forecast",N('VIC-2'!AH20)>0),'VIC-2'!AH20,IFERROR('VIC-2'!X20*1,0)) | H13: =IF(AND($B13="Forecast",N('QLD-2'!AH20)>0),'QLD-2'!AH20,IFERROR('QLD-2'!X20*1,0)) | I13: =IF(AND($B13="Forecast",N('SA-1'!AH20)>0),'SA-1'!AH20,IFERROR('SA-1'!X20*1,0)) | J13: =IF(AND($B13="Forecast",N('WA-1'!AH20)>0),'WA-1'!AH20,IFERROR('WA-1'!X20*1,0)) | K13: =IF(AND($B13="Forecast",N('IDC-NSW'!AH20)>0),'IDC-NSW'!AH20,IFERROR('IDC-NSW'!X20*1,0)) | L13: =IF(AND($B13="Forecast",N('IDC-VIC'!AH20)>0),'IDC-VIC'!AH20,IFERROR('IDC-VIC'!X20*1,0)) | AJ13: =IF($B13="Actual",C13,IF(Y13<>"",Y13,C13+N(N13))) | AK13: =IF($B13="Actual",D13,IF(Z13<>"",Z13,D13+N(O13))) | AL13: =IF($B13="Actual",E13,IF(AA13<>"",AA13,E13+N(P13))) | AM13: =IF($B13="Actual",F13,IF(AB13<>"",AB13,F13+N(Q13))) | AN13: =IF($B13="Actual",G13,IF(AC13<>"",AC13,G13+N(R13))) | AO13: =IF($B13="Actual",H13,IF(AD13<>"",AD13,H13+N(S13))) | AP13: =IF($B13="Actual",I13,IF(AE13<>"",AE13,I13+N(T13))) | AQ13: =IF($B13="Actual",J13,IF(AF13<>"",AF13,J13+N(U13))) | ... AS13: =IF($B13="Actual",L13,IF(AH13<>"",AH13,L13+N(W13)))
A14: 45839 | B14: =IF(A14<=LastActual,"Actual","Forecast") | C14: =IF(AND($B14="Forecast",N('NSW-1'!AH21)>0),'NSW-1'!AH21,IFERROR('NSW-1'!X21*1,0)) | D14: =IF(AND($B14="Forecast",N('VIC-1'!AH21)>0),'VIC-1'!AH21,IFERROR('VIC-1'!X21*1,0)) | E14: =IF(AND($B14="Forecast",N('QLD-1'!AH21)>0),'QLD-1'!AH21,IFERROR('QLD-1'!X21*1,0)) | F14: =IF(AND($B14="Forecast",N('NSW-2'!AH21)>0),'NSW-2'!AH21,IFERROR('NSW-2'!X21*1,0)) | G14: =IF(AND($B14="Forecast",N('VIC-2'!AH21)>0),'VIC-2'!AH21,IFERROR('VIC-2'!X21*1,0)) | H14: =IF(AND($B14="Forecast",N('QLD-2'!AH21)>0),'QLD-2'!AH21,IFERROR('QLD-2'!X21*1,0)) | I14: =IF(AND($B14="Forecast",N('SA-1'!AH21)>0),'SA-1'!AH21,IFERROR('SA-1'!X21*1,0)) | J14: =IF(AND($B14="Forecast",N('WA-1'!AH21)>0),'WA-1'!AH21,IFERROR('WA-1'!X21*1,0)) | K14: =IF(AND($B14="Forecast",N('IDC-NSW'!AH21)>0),'IDC-NSW'!AH21,IFERROR('IDC-NSW'!X21*1,0)) | L14: =IF(AND($B14="Forecast",N('IDC-VIC'!AH21)>0),'IDC-VIC'!AH21,IFERROR('IDC-VIC'!X21*1,0)) | AJ14: =IF($B14="Actual",C14,IF(Y14<>"",Y14,C14+N(N14))) | AK14: =IF($B14="Actual",D14,IF(Z14<>"",Z14,D14+N(O14))) | AL14: =IF($B14="Actual",E14,IF(AA14<>"",AA14,E14+N(P14))) | AM14: =IF($B14="Actual",F14,IF(AB14<>"",AB14,F14+N(Q14))) | AN14: =IF($B14="Actual",G14,IF(AC14<>"",AC14,G14+N(R14))) | AO14: =IF($B14="Actual",H14,IF(AD14<>"",AD14,H14+N(S14))) | AP14: =IF($B14="Actual",I14,IF(AE14<>"",AE14,I14+N(T14))) | AQ14: =IF($B14="Actual",J14,IF(AF14<>"",AF14,J14+N(U14))) | ... AS14: =IF($B14="Actual",L14,IF(AH14<>"",AH14,L14+N(W14)))
A15: 45870 | B15: =IF(A15<=LastActual,"Actual","Forecast") | C15: =IF(AND($B15="Forecast",N('NSW-1'!AH22)>0),'NSW-1'!AH22,IFERROR('NSW-1'!X22*1,0)) | D15: =IF(AND($B15="Forecast",N('VIC-1'!AH22)>0),'VIC-1'!AH22,IFERROR('VIC-1'!X22*1,0)) | E15: =IF(AND($B15="Forecast",N('QLD-1'!AH22)>0),'QLD-1'!AH22,IFERROR('QLD-1'!X22*1,0)) | F15: =IF(AND($B15="Forecast",N('NSW-2'!AH22)>0),'NSW-2'!AH22,IFERROR('NSW-2'!X22*1,0)) | G15: =IF(AND($B15="Forecast",N('VIC-2'!AH22)>0),'VIC-2'!AH22,IFERROR('VIC-2'!X22*1,0)) | H15: =IF(AND($B15="Forecast",N('QLD-2'!AH22)>0),'QLD-2'!AH22,IFERROR('QLD-2'!X22*1,0)) | I15: =IF(AND($B15="Forecast",N('SA-1'!AH22)>0),'SA-1'!AH22,IFERROR('SA-1'!X22*1,0)) | J15: =IF(AND($B15="Forecast",N('WA-1'!AH22)>0),'WA-1'!AH22,IFERROR('WA-1'!X22*1,0)) | K15: =IF(AND($B15="Forecast",N('IDC-NSW'!AH22)>0),'IDC-NSW'!AH22,IFERROR('IDC-NSW'!X22*1,0)) | L15: =IF(AND($B15="Forecast",N('IDC-VIC'!AH22)>0),'IDC-VIC'!AH22,IFERROR('IDC-VIC'!X22*1,0)) | AJ15: =IF($B15="Actual",C15,IF(Y15<>"",Y15,C15+N(N15))) | AK15: =IF($B15="Actual",D15,IF(Z15<>"",Z15,D15+N(O15))) | AL15: =IF($B15="Actual",E15,IF(AA15<>"",AA15,E15+N(P15))) | AM15: =IF($B15="Actual",F15,IF(AB15<>"",AB15,F15+N(Q15))) | AN15: =IF($B15="Actual",G15,IF(AC15<>"",AC15,G15+N(R15))) | AO15: =IF($B15="Actual",H15,IF(AD15<>"",AD15,H15+N(S15))) | AP15: =IF($B15="Actual",I15,IF(AE15<>"",AE15,I15+N(T15))) | AQ15: =IF($B15="Actual",J15,IF(AF15<>"",AF15,J15+N(U15))) | ... AS15: =IF($B15="Actual",L15,IF(AH15<>"",AH15,L15+N(W15)))
A16: 45901 | B16: =IF(A16<=LastActual,"Actual","Forecast") | C16: =IF(AND($B16="Forecast",N('NSW-1'!AH23)>0),'NSW-1'!AH23,IFERROR('NSW-1'!X23*1,0)) | D16: =IF(AND($B16="Forecast",N('VIC-1'!AH23)>0),'VIC-1'!AH23,IFERROR('VIC-1'!X23*1,0)) | E16: =IF(AND($B16="Forecast",N('QLD-1'!AH23)>0),'QLD-1'!AH23,IFERROR('QLD-1'!X23*1,0)) | F16: =IF(AND($B16="Forecast",N('NSW-2'!AH23)>0),'NSW-2'!AH23,IFERROR('NSW-2'!X23*1,0)) | G16: =IF(AND($B16="Forecast",N('VIC-2'!AH23)>0),'VIC-2'!AH23,IFERROR('VIC-2'!X23*1,0)) | H16: =IF(AND($B16="Forecast",N('QLD-2'!AH23)>0),'QLD-2'!AH23,IFERROR('QLD-2'!X23*1,0)) | I16: =IF(AND($B16="Forecast",N('SA-1'!AH23)>0),'SA-1'!AH23,IFERROR('SA-1'!X23*1,0)) | J16: =IF(AND($B16="Forecast",N('WA-1'!AH23)>0),'WA-1'!AH23,IFERROR('WA-1'!X23*1,0)) | K16: =IF(AND($B16="Forecast",N('IDC-NSW'!AH23)>0),'IDC-NSW'!AH23,IFERROR('IDC-NSW'!X23*1,0)) | L16: =IF(AND($B16="Forecast",N('IDC-VIC'!AH23)>0),'IDC-VIC'!AH23,IFERROR('IDC-VIC'!X23*1,0)) | AJ16: =IF($B16="Actual",C16,IF(Y16<>"",Y16,C16+N(N16))) | AK16: =IF($B16="Actual",D16,IF(Z16<>"",Z16,D16+N(O16))) | AL16: =IF($B16="Actual",E16,IF(AA16<>"",AA16,E16+N(P16))) | AM16: =IF($B16="Actual",F16,IF(AB16<>"",AB16,F16+N(Q16))) | AN16: =IF($B16="Actual",G16,IF(AC16<>"",AC16,G16+N(R16))) | AO16: =IF($B16="Actual",H16,IF(AD16<>"",AD16,H16+N(S16))) | AP16: =IF($B16="Actual",I16,IF(AE16<>"",AE16,I16+N(T16))) | AQ16: =IF($B16="Actual",J16,IF(AF16<>"",AF16,J16+N(U16))) | ... AS16: =IF($B16="Actual",L16,IF(AH16<>"",AH16,L16+N(W16)))
A17: 45931 | B17: =IF(A17<=LastActual,"Actual","Forecast") | C17: =IF(AND($B17="Forecast",N('NSW-1'!AH24)>0),'NSW-1'!AH24,IFERROR('NSW-1'!X24*1,0)) | D17: =IF(AND($B17="Forecast",N('VIC-1'!AH24)>0),'VIC-1'!AH24,IFERROR('VIC-1'!X24*1,0)) | E17: =IF(AND($B17="Forecast",N('QLD-1'!AH24)>0),'QLD-1'!AH24,IFERROR('QLD-1'!X24*1,0)) | F17: =IF(AND($B17="Forecast",N('NSW-2'!AH24)>0),'NSW-2'!AH24,IFERROR('NSW-2'!X24*1,0)) | G17: =IF(AND($B17="Forecast",N('VIC-2'!AH24)>0),'VIC-2'!AH24,IFERROR('VIC-2'!X24*1,0)) | H17: =IF(AND($B17="Forecast",N('QLD-2'!AH24)>0),'QLD-2'!AH24,IFERROR('QLD-2'!X24*1,0)) | I17: =IF(AND($B17="Forecast",N('SA-1'!AH24)>0),'SA-1'!AH24,IFERROR('SA-1'!X24*1,0)) | J17: =IF(AND($B17="Forecast",N('WA-1'!AH24)>0),'WA-1'!AH24,IFERROR('WA-1'!X24*1,0)) | K17: =IF(AND($B17="Forecast",N('IDC-NSW'!AH24)>0),'IDC-NSW'!AH24,IFERROR('IDC-NSW'!X24*1,0)) | L17: =IF(AND($B17="Forecast",N('IDC-VIC'!AH24)>0),'IDC-VIC'!AH24,IFERROR('IDC-VIC'!X24*1,0)) | AJ17: =IF($B17="Actual",C17,IF(Y17<>"",Y17,C17+N(N17))) | AK17: =IF($B17="Actual",D17,IF(Z17<>"",Z17,D17+N(O17))) | AL17: =IF($B17="Actual",E17,IF(AA17<>"",AA17,E17+N(P17))) | AM17: =IF($B17="Actual",F17,IF(AB17<>"",AB17,F17+N(Q17))) | AN17: =IF($B17="Actual",G17,IF(AC17<>"",AC17,G17+N(R17))) | AO17: =IF($B17="Actual",H17,IF(AD17<>"",AD17,H17+N(S17))) | AP17: =IF($B17="Actual",I17,IF(AE17<>"",AE17,I17+N(T17))) | AQ17: =IF($B17="Actual",J17,IF(AF17<>"",AF17,J17+N(U17))) | ... AS17: =IF($B17="Actual",L17,IF(AH17<>"",AH17,L17+N(W17)))
A18: 45962 | B18: =IF(A18<=LastActual,"Actual","Forecast") | C18: =IF(AND($B18="Forecast",N('NSW-1'!AH25)>0),'NSW-1'!AH25,IFERROR('NSW-1'!X25*1,0)) | D18: =IF(AND($B18="Forecast",N('VIC-1'!AH25)>0),'VIC-1'!AH25,IFERROR('VIC-1'!X25*1,0)) | E18: =IF(AND($B18="Forecast",N('QLD-1'!AH25)>0),'QLD-1'!AH25,IFERROR('QLD-1'!X25*1,0)) | F18: =IF(AND($B18="Forecast",N('NSW-2'!AH25)>0),'NSW-2'!AH25,IFERROR('NSW-2'!X25*1,0)) | G18: =IF(AND($B18="Forecast",N('VIC-2'!AH25)>0),'VIC-2'!AH25,IFERROR('VIC-2'!X25*1,0)) | H18: =IF(AND($B18="Forecast",N('QLD-2'!AH25)>0),'QLD-2'!AH25,IFERROR('QLD-2'!X25*1,0)) | I18: =IF(AND($B18="Forecast",N('SA-1'!AH25)>0),'SA-1'!AH25,IFERROR('SA-1'!X25*1,0)) | J18: =IF(AND($B18="Forecast",N('WA-1'!AH25)>0),'WA-1'!AH25,IFERROR('WA-1'!X25*1,0)) | K18: =IF(AND($B18="Forecast",N('IDC-NSW'!AH25)>0),'IDC-NSW'!AH25,IFERROR('IDC-NSW'!X25*1,0)) | L18: =IF(AND($B18="Forecast",N('IDC-VIC'!AH25)>0),'IDC-VIC'!AH25,IFERROR('IDC-VIC'!X25*1,0)) | AJ18: =IF($B18="Actual",C18,IF(Y18<>"",Y18,C18+N(N18))) | AK18: =IF($B18="Actual",D18,IF(Z18<>"",Z18,D18+N(O18))) | AL18: =IF($B18="Actual",E18,IF(AA18<>"",AA18,E18+N(P18))) | AM18: =IF($B18="Actual",F18,IF(AB18<>"",AB18,F18+N(Q18))) | AN18: =IF($B18="Actual",G18,IF(AC18<>"",AC18,G18+N(R18))) | AO18: =IF($B18="Actual",H18,IF(AD18<>"",AD18,H18+N(S18))) | AP18: =IF($B18="Actual",I18,IF(AE18<>"",AE18,I18+N(T18))) | AQ18: =IF($B18="Actual",J18,IF(AF18<>"",AF18,J18+N(U18))) | ... AS18: =IF($B18="Actual",L18,IF(AH18<>"",AH18,L18+N(W18)))
A19: 45992 | B19: =IF(A19<=LastActual,"Actual","Forecast") | C19: =IF(AND($B19="Forecast",N('NSW-1'!AH26)>0),'NSW-1'!AH26,IFERROR('NSW-1'!X26*1,0)) | D19: =IF(AND($B19="Forecast",N('VIC-1'!AH26)>0),'VIC-1'!AH26,IFERROR('VIC-1'!X26*1,0)) | E19: =IF(AND($B19="Forecast",N('QLD-1'!AH26)>0),'QLD-1'!AH26,IFERROR('QLD-1'!X26*1,0)) | F19: =IF(AND($B19="Forecast",N('NSW-2'!AH26)>0),'NSW-2'!AH26,IFERROR('NSW-2'!X26*1,0)) | G19: =IF(AND($B19="Forecast",N('VIC-2'!AH26)>0),'VIC-2'!AH26,IFERROR('VIC-2'!X26*1,0)) | H19: =IF(AND($B19="Forecast",N('QLD-2'!AH26)>0),'QLD-2'!AH26,IFERROR('QLD-2'!X26*1,0)) | I19: =IF(AND($B19="Forecast",N('SA-1'!AH26)>0),'SA-1'!AH26,IFERROR('SA-1'!X26*1,0)) | J19: =IF(AND($B19="Forecast",N('WA-1'!AH26)>0),'WA-1'!AH26,IFERROR('WA-1'!X26*1,0)) | K19: =IF(AND($B19="Forecast",N('IDC-NSW'!AH26)>0),'IDC-NSW'!AH26,IFERROR('IDC-NSW'!X26*1,0)) | L19: =IF(AND($B19="Forecast",N('IDC-VIC'!AH26)>0),'IDC-VIC'!AH26,IFERROR('IDC-VIC'!X26*1,0)) | AJ19: =IF($B19="Actual",C19,IF(Y19<>"",Y19,C19+N(N19))) | AK19: =IF($B19="Actual",D19,IF(Z19<>"",Z19,D19+N(O19))) | AL19: =IF($B19="Actual",E19,IF(AA19<>"",AA19,E19+N(P19))) | AM19: =IF($B19="Actual",F19,IF(AB19<>"",AB19,F19+N(Q19))) | AN19: =IF($B19="Actual",G19,IF(AC19<>"",AC19,G19+N(R19))) | AO19: =IF($B19="Actual",H19,IF(AD19<>"",AD19,H19+N(S19))) | AP19: =IF($B19="Actual",I19,IF(AE19<>"",AE19,I19+N(T19))) | AQ19: =IF($B19="Actual",J19,IF(AF19<>"",AF19,J19+N(U19))) | ... AS19: =IF($B19="Actual",L19,IF(AH19<>"",AH19,L19+N(W19)))
... A55: 47088 | B55: =IF(A55<=LastActual,"Actual","Forecast") | C55: =IF(AND($B55="Forecast",N('NSW-1'!AH62)>0),'NSW-1'!AH62,IFERROR('NSW-1'!X62*1,0)) | D55: =IF(AND($B55="Forecast",N('VIC-1'!AH62)>0),'VIC-1'!AH62,IFERROR('VIC-1'!X62*1,0)) | E55: =IF(AND($B55="Forecast",N('QLD-1'!AH62)>0),'QLD-1'!AH62,IFERROR('QLD-1'!X62*1,0)) | F55: =IF(AND($B55="Forecast",N('NSW-2'!AH62)>0),'NSW-2'!AH62,IFERROR('NSW-2'!X62*1,0)) | G55: =IF(AND($B55="Forecast",N('VIC-2'!AH62)>0),'VIC-2'!AH62,IFERROR('VIC-2'!X62*1,0)) | H55: =IF(AND($B55="Forecast",N('QLD-2'!AH62)>0),'QLD-2'!AH62,IFERROR('QLD-2'!X62*1,0)) | I55: =IF(AND($B55="Forecast",N('SA-1'!AH62)>0),'SA-1'!AH62,IFERROR('SA-1'!X62*1,0)) | J55: =IF(AND($B55="Forecast",N('WA-1'!AH62)>0),'WA-1'!AH62,IFERROR('WA-1'!X62*1,0)) | K55: =IF(AND($B55="Forecast",N('IDC-NSW'!AH62)>0),'IDC-NSW'!AH62,IFERROR('IDC-NSW'!X62*1,0)) | L55: =IF(AND($B55="Forecast",N('IDC-VIC'!AH62)>0),'IDC-VIC'!AH62,IFERROR('IDC-VIC'!X62*1,0)) | AJ55: =IF($B55="Actual",C55,IF(Y55<>"",Y55,C55+N(N55))) | AK55: =IF($B55="Actual",D55,IF(Z55<>"",Z55,D55+N(O55))) | AL55: =IF($B55="Actual",E55,IF(AA55<>"",AA55,E55+N(P55))) | AM55: =IF($B55="Actual",F55,IF(AB55<>"",AB55,F55+N(Q55))) | AN55: =IF($B55="Actual",G55,IF(AC55<>"",AC55,G55+N(R55))) | AO55: =IF($B55="Actual",H55,IF(AD55<>"",AD55,H55+N(S55))) | AP55: =IF($B55="Actual",I55,IF(AE55<>"",AE55,I55+N(T55))) | AQ55: =IF($B55="Actual",J55,IF(AF55<>"",AF55,J55+N(U55))) | ... AS55: =IF($B55="Actual",L55,IF(AH55<>"",AH55,L55+N(W55)))

Sheet CPLH_Breakdown
A1: CPLH breakdown: national CPLH target -> site CPLH by month
A2: Type a national CPLH target for a year. Every included site's CPLH (actual, else same month last year) is scaled by one
A3: factor, so the year's national CPLH (included sites' cases / hours, actual months included) hits the target. Each site keeps
A4: its own level and seasonal shape. Blank target = no change. Excluded sites keep their same-month-last-year CPLH.
A5: Copy the paste column (far right) into Plan_Inputs column D, or set 'Plan CPLH source' on Inputs to National breakdown.
A8: FY | B8: National CPLH target | C8: Included cases | D8: Actual hours | E8: Fcst hours at base CPLH | F8: Base national CPLH | G8: Uplift factor | H8: Resulting national CPLH
A9: 2026 | C9: =SUMIFS($BG$20:$BG$67,$C$20:$C$67,$A9) | D9: =SUMIFS($BH$20:$BH$67,$C$20:$C$67,$A9,$B$20:$B$67,"Actual") | E9: =SUMIFS($BH$20:$BH$67,$C$20:$C$67,$A9,$B$20:$B$67,"Forecast") | F9: =IFERROR(C9/(D9+E9),0) | G9: =IF(B9="",1,IF(C9/B9-D9<=0,NA(),E9/(C9/B9-D9))) | H9: =IFERROR(C9/SUMIFS($BI$20:$BI$67,$C$20:$C$67,$A9),0) | I9: Cases in m. Uplift factor 1.03 = every included site's CPLH +3% in that year's forecast months.
A10: 2027 | B10: 80.9 | C10: =SUMIFS($BG$20:$BG$67,$C$20:$C$67,$A10) | D10: =SUMIFS($BH$20:$BH$67,$C$20:$C$67,$A10,$B$20:$B$67,"Actual") | E10: =SUMIFS($BH$20:$BH$67,$C$20:$C$67,$A10,$B$20:$B$67,"Forecast") | F10: =IFERROR(C10/(D10+E10),0) | G10: =IF(B10="",1,IF(C10/B10-D10<=0,NA(),E10/(C10/B10-D10))) | H10: =IFERROR(C10/SUMIFS($BI$20:$BI$67,$C$20:$C$67,$A10),0)
A11: 2028 | B11: 81.4 | C11: =SUMIFS($BG$20:$BG$67,$C$20:$C$67,$A11) | D11: =SUMIFS($BH$20:$BH$67,$C$20:$C$67,$A11,$B$20:$B$67,"Actual") | E11: =SUMIFS($BH$20:$BH$67,$C$20:$C$67,$A11,$B$20:$B$67,"Forecast") | F11: =IFERROR(C11/(D11+E11),0) | G11: =IF(B11="",1,IF(C11/B11-D11<=0,NA(),E11/(C11/B11-D11))) | H11: =IFERROR(C11/SUMIFS($BI$20:$BI$67,$C$20:$C$67,$A11),0)
C14: Site | D14: =Inputs!$A$36 | E14: =Inputs!$A$37 | F14: =Inputs!$A$38 | G14: =Inputs!$A$39 | H14: =Inputs!$A$40 | I14: =Inputs!$A$41 | J14: =Inputs!$A$42 | K14: =Inputs!$A$43 | L14: =Inputs!$A$44 | M14: =Inputs!$A$45
C15: Include | D15: Yes | E15: Yes | F15: Yes | G15: Yes | H15: Yes | I15: Yes | J15: Yes | K15: Yes | L15: No | M15: No
D18: Base CPLH (actual, else same month LY) | O18: Cases (Cases_Forecast used) | Z18: Hours at base CPLH | AK18: Suggested CPLH | AV18: Hours at suggested CPLH | BG18: National (included sites) | BN18: To paste into Plan_Inputs column D (values)
A19: Month | B19: Status | C19: FY | D19: =Inputs!$A$36 | E19: =Inputs!$A$37 | F19: =Inputs!$A$38 | G19: =Inputs!$A$39 | H19: =Inputs!$A$40 | I19: =Inputs!$A$41 | J19: =Inputs!$A$42 | K19: =Inputs!$A$43 | L19: =Inputs!$A$44 | M19: =Inputs!$A$45 | O19: =Inputs!$A$36 | P19: =Inputs!$A$37 | Q19: =Inputs!$A$38 | R19: =Inputs!$A$39 | S19: =Inputs!$A$40 | T19: =Inputs!$A$41 | U19: =Inputs!$A$42 | V19: =Inputs!$A$43 | W19: =Inputs!$A$44 | X19: =Inputs!$A$45 | Z19: =Inputs!$A$36 | AA19: =Inputs!$A$37 | AB19: =Inputs!$A$38 | AC19: =Inputs!$A$39 | AD19: =Inputs!$A$40 | AE19: =Inputs!$A$41 | AF19: =Inputs!$A$42 | AG19: =Inputs!$A$43 | AH19: =Inputs!$A$44 | AI19: =Inputs!$A$45 | AK19: =Inputs!$A$36 | AL19: =Inputs!$A$37 | AM19: =Inputs!$A$38 | AN19: =Inputs!$A$39 | AO19: =Inputs!$A$40 | AP19: =Inputs!$A$41 | AQ19: =Inputs!$A$42 | AR19: =Inputs!$A$43 | AS19: =Inputs!$A$44 | AT19: =Inputs!$A$45 | AV19: =Inputs!$A$36 | AW19: =Inputs!$A$37 | AX19: =Inputs!$A$38 | AY19: =Inputs!$A$39 | AZ19: =Inputs!$A$40 | BA19: =Inputs!$A$41 | BB19: =Inputs!$A$42 | BC19: =Inputs!$A$43 | BD19: =Inputs!$A$44 | BE19: =Inputs!$A$45 | BG19: Cases | BH19: Hours at base CPLH | BI19: Hours at suggested CPLH | BJ19: Base CPLH | BK19: Suggested CPLH | BL19: Uplift factor | BN19: Month | BO19: Site | BP19: Suggested CPLH
A20: 45658 | B20: =IF(A20<=LastActual,"Actual","Forecast") | C20: =YEAR(A20) | D20: =IFERROR('NSW-1'!X15*1,0) | E20: =IFERROR('VIC-1'!X15*1,0) | F20: =IFERROR('QLD-1'!X15*1,0) | G20: =IFERROR('NSW-2'!X15*1,0) | H20: =IFERROR('VIC-2'!X15*1,0) | I20: =IFERROR('QLD-2'!X15*1,0) | J20: =IFERROR('SA-1'!X15*1,0) | K20: =IFERROR('WA-1'!X15*1,0) | L20: =IFERROR('IDC-NSW'!X15*1,0) | M20: =IFERROR('IDC-VIC'!X15*1,0) | O20: =Cases_Forecast!AJ8 | P20: =Cases_Forecast!AK8 | Q20: =Cases_Forecast!AL8 | R20: =Cases_Forecast!AM8 | S20: =Cases_Forecast!AN8 | T20: =Cases_Forecast!AO8 | U20: =Cases_Forecast!AP8 | V20: =Cases_Forecast!AQ8 | ... X20: =Cases_Forecast!AS8 | Z20: =IFERROR(O20/D20,0) | AA20: =IFERROR(P20/E20,0) | AB20: =IFERROR(Q20/F20,0) | AC20: =IFERROR(R20/G20,0) | AD20: =IFERROR(S20/H20,0) | AE20: =IFERROR(T20/I20,0) | AF20: =IFERROR(U20/J20,0) | AG20: =IFERROR(V20/K20,0) | ... AI20: =IFERROR(X20/M20,0) | AK20: =IF(D$15="Yes",D20*$BL20,D20) | AL20: =IF(E$15="Yes",E20*$BL20,E20) | AM20: =IF(F$15="Yes",F20*$BL20,F20) | AN20: =IF(G$15="Yes",G20*$BL20,G20) | AO20: =IF(H$15="Yes",H20*$BL20,H20) | AP20: =IF(I$15="Yes",I20*$BL20,I20) | AQ20: =IF(J$15="Yes",J20*$BL20,J20) | AR20: =IF(K$15="Yes",K20*$BL20,K20) | ... AT20: =IF(M$15="Yes",M20*$BL20,M20) | AV20: =IFERROR(O20/AK20,0) | AW20: =IFERROR(P20/AL20,0) | AX20: =IFERROR(Q20/AM20,0) | AY20: =IFERROR(R20/AN20,0) | AZ20: =IFERROR(S20/AO20,0) | BA20: =IFERROR(T20/AP20,0) | BB20: =IFERROR(U20/AQ20,0) | BC20: =IFERROR(V20/AR20,0) | ... BE20: =IFERROR(X20/AT20,0) | BG20: =SUMPRODUCT(($D$15:$M$15="Yes")*O20:X20) | BH20: =SUMPRODUCT(($D$15:$M$15="Yes")*Z20:AI20) | BI20: =SUMPRODUCT(($D$15:$M$15="Yes")*AV20:BE20) | BJ20: =IFERROR(BG20/BH20,0) | BK20: =IFERROR(BG20/BI20,0) | BL20: =IF(B20="Actual",1,INDEX($G$9:$G$11,MATCH(C20,$A$9:$A$11,0))) | BN20: 46023 | BO20: =Inputs!$A$36 | BP20: =AK32
A21: 45689 | B21: =IF(A21<=LastActual,"Actual","Forecast") | C21: =YEAR(A21) | D21: =IFERROR('NSW-1'!X16*1,0) | E21: =IFERROR('VIC-1'!X16*1,0) | F21: =IFERROR('QLD-1'!X16*1,0) | G21: =IFERROR('NSW-2'!X16*1,0) | H21: =IFERROR('VIC-2'!X16*1,0) | I21: =IFERROR('QLD-2'!X16*1,0) | J21: =IFERROR('SA-1'!X16*1,0) | K21: =IFERROR('WA-1'!X16*1,0) | L21: =IFERROR('IDC-NSW'!X16*1,0) | M21: =IFERROR('IDC-VIC'!X16*1,0) | O21: =Cases_Forecast!AJ9 | P21: =Cases_Forecast!AK9 | Q21: =Cases_Forecast!AL9 | R21: =Cases_Forecast!AM9 | S21: =Cases_Forecast!AN9 | T21: =Cases_Forecast!AO9 | U21: =Cases_Forecast!AP9 | V21: =Cases_Forecast!AQ9 | ... X21: =Cases_Forecast!AS9 | Z21: =IFERROR(O21/D21,0) | AA21: =IFERROR(P21/E21,0) | AB21: =IFERROR(Q21/F21,0) | AC21: =IFERROR(R21/G21,0) | AD21: =IFERROR(S21/H21,0) | AE21: =IFERROR(T21/I21,0) | AF21: =IFERROR(U21/J21,0) | AG21: =IFERROR(V21/K21,0) | ... AI21: =IFERROR(X21/M21,0) | AK21: =IF(D$15="Yes",D21*$BL21,D21) | AL21: =IF(E$15="Yes",E21*$BL21,E21) | AM21: =IF(F$15="Yes",F21*$BL21,F21) | AN21: =IF(G$15="Yes",G21*$BL21,G21) | AO21: =IF(H$15="Yes",H21*$BL21,H21) | AP21: =IF(I$15="Yes",I21*$BL21,I21) | AQ21: =IF(J$15="Yes",J21*$BL21,J21) | AR21: =IF(K$15="Yes",K21*$BL21,K21) | ... AT21: =IF(M$15="Yes",M21*$BL21,M21) | AV21: =IFERROR(O21/AK21,0) | AW21: =IFERROR(P21/AL21,0) | AX21: =IFERROR(Q21/AM21,0) | AY21: =IFERROR(R21/AN21,0) | AZ21: =IFERROR(S21/AO21,0) | BA21: =IFERROR(T21/AP21,0) | BB21: =IFERROR(U21/AQ21,0) | BC21: =IFERROR(V21/AR21,0) | ... BE21: =IFERROR(X21/AT21,0) | BG21: =SUMPRODUCT(($D$15:$M$15="Yes")*O21:X21) | BH21: =SUMPRODUCT(($D$15:$M$15="Yes")*Z21:AI21) | BI21: =SUMPRODUCT(($D$15:$M$15="Yes")*AV21:BE21) | BJ21: =IFERROR(BG21/BH21,0) | BK21: =IFERROR(BG21/BI21,0) | BL21: =IF(B21="Actual",1,INDEX($G$9:$G$11,MATCH(C21,$A$9:$A$11,0))) | BN21: 46023 | BO21: =Inputs!$A$37 | BP21: =AL32
A22: 45717 | B22: =IF(A22<=LastActual,"Actual","Forecast") | C22: =YEAR(A22) | D22: =IFERROR('NSW-1'!X17*1,0) | E22: =IFERROR('VIC-1'!X17*1,0) | F22: =IFERROR('QLD-1'!X17*1,0) | G22: =IFERROR('NSW-2'!X17*1,0) | H22: =IFERROR('VIC-2'!X17*1,0) | I22: =IFERROR('QLD-2'!X17*1,0) | J22: =IFERROR('SA-1'!X17*1,0) | K22: =IFERROR('WA-1'!X17*1,0) | L22: =IFERROR('IDC-NSW'!X17*1,0) | M22: =IFERROR('IDC-VIC'!X17*1,0) | O22: =Cases_Forecast!AJ10 | P22: =Cases_Forecast!AK10 | Q22: =Cases_Forecast!AL10 | R22: =Cases_Forecast!AM10 | S22: =Cases_Forecast!AN10 | T22: =Cases_Forecast!AO10 | U22: =Cases_Forecast!AP10 | V22: =Cases_Forecast!AQ10 | ... X22: =Cases_Forecast!AS10 | Z22: =IFERROR(O22/D22,0) | AA22: =IFERROR(P22/E22,0) | AB22: =IFERROR(Q22/F22,0) | AC22: =IFERROR(R22/G22,0) | AD22: =IFERROR(S22/H22,0) | AE22: =IFERROR(T22/I22,0) | AF22: =IFERROR(U22/J22,0) | AG22: =IFERROR(V22/K22,0) | ... AI22: =IFERROR(X22/M22,0) | AK22: =IF(D$15="Yes",D22*$BL22,D22) | AL22: =IF(E$15="Yes",E22*$BL22,E22) | AM22: =IF(F$15="Yes",F22*$BL22,F22) | AN22: =IF(G$15="Yes",G22*$BL22,G22) | AO22: =IF(H$15="Yes",H22*$BL22,H22) | AP22: =IF(I$15="Yes",I22*$BL22,I22) | AQ22: =IF(J$15="Yes",J22*$BL22,J22) | AR22: =IF(K$15="Yes",K22*$BL22,K22) | ... AT22: =IF(M$15="Yes",M22*$BL22,M22) | AV22: =IFERROR(O22/AK22,0) | AW22: =IFERROR(P22/AL22,0) | AX22: =IFERROR(Q22/AM22,0) | AY22: =IFERROR(R22/AN22,0) | AZ22: =IFERROR(S22/AO22,0) | BA22: =IFERROR(T22/AP22,0) | BB22: =IFERROR(U22/AQ22,0) | BC22: =IFERROR(V22/AR22,0) | ... BE22: =IFERROR(X22/AT22,0) | BG22: =SUMPRODUCT(($D$15:$M$15="Yes")*O22:X22) | BH22: =SUMPRODUCT(($D$15:$M$15="Yes")*Z22:AI22) | BI22: =SUMPRODUCT(($D$15:$M$15="Yes")*AV22:BE22) | BJ22: =IFERROR(BG22/BH22,0) | BK22: =IFERROR(BG22/BI22,0) | BL22: =IF(B22="Actual",1,INDEX($G$9:$G$11,MATCH(C22,$A$9:$A$11,0))) | BN22: 46023 | BO22: =Inputs!$A$38 | BP22: =AM32
